2025-04-20 20:17:31,323 INFO    MainThread:1988 [wandb_setup.py:_flush():67] Current SDK version is 0.19.9
2025-04-20 20:17:31,323 INFO    MainThread:1988 [wandb_setup.py:_flush():67] Configure stats pid to 1988
2025-04-20 20:17:31,323 INFO    MainThread:1988 [wandb_setup.py:_flush():67] Loading settings from C:\Users\Administrator\.config\wandb\settings
2025-04-20 20:17:31,323 INFO    MainThread:1988 [wandb_setup.py:_flush():67] Loading settings from C:\Users\Administrator\Desktop\di725-term-project\di725-project\notebooks\wandb\settings
2025-04-20 20:17:31,323 INFO    MainThread:1988 [wandb_setup.py:_flush():67] Loading settings from environment variables
2025-04-20 20:17:31,324 INFO    MainThread:1988 [wandb_init.py:setup_run_log_directory():662] Logging user logs to C:\Users\Administrator\Desktop\di725-term-project\di725-project\notebooks\wandb\run-20250420_201731-mybg6dpb\logs\debug.log
2025-04-20 20:17:31,324 INFO    MainThread:1988 [wandb_init.py:setup_run_log_directory():663] Logging internal logs to C:\Users\Administrator\Desktop\di725-term-project\di725-project\notebooks\wandb\run-20250420_201731-mybg6dpb\logs\debug-internal.log
2025-04-20 20:17:31,324 INFO    MainThread:1988 [wandb_init.py:monkeypatch_ipython():581] configuring jupyter hooks <wandb.sdk.wandb_init._WandbInit object at 0x0000022D58DAC7C0>
2025-04-20 20:17:31,325 INFO    MainThread:1988 [wandb_init.py:init():781] calling init triggers
2025-04-20 20:17:31,325 INFO    MainThread:1988 [wandb_init.py:init():786] wandb.init called with sweep_config: {}
config: {'_wandb': {}}
2025-04-20 20:17:31,325 INFO    MainThread:1988 [wandb_init.py:init():809] starting backend
2025-04-20 20:17:31,325 INFO    MainThread:1988 [wandb_init.py:init():813] sending inform_init request
2025-04-20 20:17:31,334 INFO    MainThread:1988 [backend.py:_multiprocessing_setup():101] multiprocessing start_methods=spawn, using: spawn
2025-04-20 20:17:31,335 INFO    MainThread:1988 [wandb_init.py:init():823] backend started and connected
2025-04-20 20:17:31,339 INFO    MainThread:1988 [wandb_run.py:_label_probe_notebook():1267] probe notebook
2025-04-20 20:17:31,340 INFO    MainThread:1988 [wandb_run.py:_label_probe_notebook():1277] Unable to probe notebook: 'NoneType' object has no attribute 'get'
2025-04-20 20:17:31,340 INFO    MainThread:1988 [wandb_init.py:init():915] updated telemetry
2025-04-20 20:17:31,485 INFO    MainThread:1988 [wandb_init.py:init():939] communicating run to backend with 90.0 second timeout
2025-04-20 20:17:31,975 INFO    MainThread:1988 [wandb_init.py:init():1014] starting run threads in backend
2025-04-20 20:17:32,351 INFO    MainThread:1988 [wandb_run.py:_console_start():2454] atexit reg
2025-04-20 20:17:32,351 INFO    MainThread:1988 [wandb_run.py:_redirect():2306] redirect: wrap_raw
2025-04-20 20:17:32,351 INFO    MainThread:1988 [wandb_run.py:_redirect():2371] Wrapping output streams.
2025-04-20 20:17:32,351 INFO    MainThread:1988 [wandb_run.py:_redirect():2394] Redirects installed.
2025-04-20 20:17:32,354 INFO    MainThread:1988 [wandb_init.py:init():1056] run started, returning control to user process
2025-04-20 20:17:32,354 INFO    MainThread:1988 [wandb_run.py:_config_callback():1327] config_cb None None {'task': 'EDA', 'script': 'eda_risc.ipynb', 'dataset': 'RISC', 'date': '2025-04-20'}
2025-04-20 20:17:32,355 INFO    MainThread:1988 [jupyter.py:save_ipynb():384] [no run ID] not saving jupyter notebook
2025-04-20 20:17:32,355 INFO    MainThread:1988 [wandb_init.py:_pause_backend():546] [no run ID] pausing backend
2025-04-20 20:17:32,359 INFO    MainThread:1988 [wandb_init.py:_resume_backend():551] [no run ID] resuming backend
2025-04-20 20:17:32,549 INFO    MainThread:1988 [jupyter.py:save_ipynb():384] [no run ID] not saving jupyter notebook
2025-04-20 20:17:32,549 INFO    MainThread:1988 [wandb_init.py:_pause_backend():546] [no run ID] pausing backend
2025-04-20 20:17:32,553 INFO    MainThread:1988 [wandb_init.py:_resume_backend():551] [no run ID] resuming backend
2025-04-20 20:17:32,565 INFO    MainThread:1988 [jupyter.py:save_ipynb():384] [no run ID] not saving jupyter notebook
2025-04-20 20:17:32,566 INFO    MainThread:1988 [wandb_init.py:_pause_backend():546] [no run ID] pausing backend
2025-04-20 20:17:32,572 INFO    MainThread:1988 [wandb_init.py:_resume_backend():551] [no run ID] resuming backend
2025-04-20 20:17:32,675 INFO    MainThread:1988 [jupyter.py:save_ipynb():384] [no run ID] not saving jupyter notebook
2025-04-20 20:17:32,675 INFO    MainThread:1988 [wandb_init.py:_pause_backend():546] [no run ID] pausing backend
2025-04-20 20:17:32,682 INFO    MainThread:1988 [wandb_init.py:_resume_backend():551] [no run ID] resuming backend
2025-04-20 20:17:32,690 INFO    MainThread:1988 [jupyter.py:save_ipynb():384] [no run ID] not saving jupyter notebook
2025-04-20 20:17:32,691 INFO    MainThread:1988 [wandb_init.py:_pause_backend():546] [no run ID] pausing backend
2025-04-20 20:17:32,698 INFO    MainThread:1988 [wandb_init.py:_resume_backend():551] [no run ID] resuming backend
2025-04-20 20:17:32,774 INFO    MainThread:1988 [jupyter.py:save_ipynb():384] [no run ID] not saving jupyter notebook
2025-04-20 20:17:32,774 INFO    MainThread:1988 [wandb_init.py:_pause_backend():546] [no run ID] pausing backend
2025-04-20 20:17:32,781 INFO    MainThread:1988 [wandb_init.py:_resume_backend():551] [no run ID] resuming backend
2025-04-20 20:17:33,851 INFO    MainThread:1988 [jupyter.py:save_ipynb():384] [no run ID] not saving jupyter notebook
2025-04-20 20:17:33,852 INFO    MainThread:1988 [wandb_init.py:_pause_backend():546] [no run ID] pausing backend
2025-04-20 20:19:03,802 WARNING MsgRouterThr:1988 [router.py:message_loop():63] [no run ID] message_loop has been closed
Traceback (most recent call last):
  File "C:\ProgramData\anaconda3\envs\di725-a2-clean\lib\site-packages\wandb\sdk\lib\sock_client.py", line 208, in _read_packet_bytes
    data = self._sock.recv(self._bufsize)
ConnectionResetError: [WinError 10054] An existing connection was forcibly closed by the remote host

The above exception was the direct cause of the following exception:

Traceback (most recent call last):
  File "C:\ProgramData\anaconda3\envs\di725-a2-clean\lib\site-packages\wandb\sdk\interface\router_sock.py", line 27, in _read_message
    return self._sock_client.read_server_response(timeout=1)
  File "C:\ProgramData\anaconda3\envs\di725-a2-clean\lib\site-packages\wandb\sdk\lib\sock_client.py", line 235, in read_server_response
    data = self._read_packet_bytes(timeout=timeout)
  File "C:\ProgramData\anaconda3\envs\di725-a2-clean\lib\site-packages\wandb\sdk\lib\sock_client.py", line 212, in _read_packet_bytes
    raise SockClientClosedError from e
wandb.sdk.lib.sock_client.SockClientClosedError

The above exception was the direct cause of the following exception:

Traceback (most recent call last):
  File "C:\ProgramData\anaconda3\envs\di725-a2-clean\lib\site-packages\wandb\sdk\interface\router.py", line 56, in message_loop
    msg = self._read_message()
  File "C:\ProgramData\anaconda3\envs\di725-a2-clean\lib\site-packages\wandb\sdk\interface\router_sock.py", line 29, in _read_message
    raise MessageRouterClosedError from e
wandb.sdk.interface.router.MessageRouterClosedError
2025-04-20 20:19:03,805 INFO    MsgRouterThr:1988 [mailbox.py:close():129] [no run ID] Closing mailbox, abandoning 1 handles.
2025-04-20 20:19:03,806 ERROR   MainThread:1988 [redirect.py:_on_write():661] [no run ID] error in stderr callback
Traceback (most recent call last):
  File "C:\ProgramData\anaconda3\envs\di725-a2-clean\lib\site-packages\wandb\sdk\lib\redirect.py", line 659, in _on_write
    cb(written_data)
  File "C:\ProgramData\anaconda3\envs\di725-a2-clean\lib\site-packages\wandb\sdk\wandb_run.py", line 2381, in <lambda>
    lambda data: self._console_raw_callback("stderr", data),
  File "C:\ProgramData\anaconda3\envs\di725-a2-clean\lib\site-packages\wandb\sdk\wandb_run.py", line 387, in wrapper
    return func(self, *args, **kwargs)
  File "C:\ProgramData\anaconda3\envs\di725-a2-clean\lib\site-packages\wandb\sdk\wandb_run.py", line 435, in wrapper_fn
    return func(self, *args, **kwargs)
  File "C:\ProgramData\anaconda3\envs\di725-a2-clean\lib\site-packages\wandb\sdk\wandb_run.py", line 1518, in _console_raw_callback
    self._backend.interface.publish_output_raw(name, data)
  File "C:\ProgramData\anaconda3\envs\di725-a2-clean\lib\site-packages\wandb\sdk\interface\interface.py", line 761, in publish_output_raw
    self._publish_output_raw(o)
  File "C:\ProgramData\anaconda3\envs\di725-a2-clean\lib\site-packages\wandb\sdk\interface\interface_shared.py", line 38, in _publish_output_raw
    self._publish(rec)
  File "C:\ProgramData\anaconda3\envs\di725-a2-clean\lib\site-packages\wandb\sdk\interface\interface_sock.py", line 39, in _publish
    self._sock_client.send_record_publish(record)
  File "C:\ProgramData\anaconda3\envs\di725-a2-clean\lib\site-packages\wandb\sdk\lib\sock_client.py", line 174, in send_record_publish
    self.send_server_request(server_req)
  File "C:\ProgramData\anaconda3\envs\di725-a2-clean\lib\site-packages\wandb\sdk\lib\sock_client.py", line 154, in send_server_request
    self._send_message(msg)
  File "C:\ProgramData\anaconda3\envs\di725-a2-clean\lib\site-packages\wandb\sdk\lib\sock_client.py", line 151, in _send_message
    self._sendall_with_error_handle(header + data)
  File "C:\ProgramData\anaconda3\envs\di725-a2-clean\lib\site-packages\wandb\sdk\lib\sock_client.py", line 130, in _sendall_with_error_handle
    sent = self._sock.send(data)
ConnectionResetError: [WinError 10054] An existing connection was forcibly closed by the remote host
2025-04-20 20:19:03,809 ERROR   MainThread:1988 [redirect.py:_on_write():661] [no run ID] error in stderr callback
Traceback (most recent call last):
  File "C:\ProgramData\anaconda3\envs\di725-a2-clean\lib\site-packages\wandb\sdk\lib\redirect.py", line 659, in _on_write
    cb(written_data)
  File "C:\ProgramData\anaconda3\envs\di725-a2-clean\lib\site-packages\wandb\sdk\wandb_run.py", line 2381, in <lambda>
    lambda data: self._console_raw_callback("stderr", data),
  File "C:\ProgramData\anaconda3\envs\di725-a2-clean\lib\site-packages\wandb\sdk\wandb_run.py", line 387, in wrapper
    return func(self, *args, **kwargs)
  File "C:\ProgramData\anaconda3\envs\di725-a2-clean\lib\site-packages\wandb\sdk\wandb_run.py", line 435, in wrapper_fn
    return func(self, *args, **kwargs)
  File "C:\ProgramData\anaconda3\envs\di725-a2-clean\lib\site-packages\wandb\sdk\wandb_run.py", line 1518, in _console_raw_callback
    self._backend.interface.publish_output_raw(name, data)
  File "C:\ProgramData\anaconda3\envs\di725-a2-clean\lib\site-packages\wandb\sdk\interface\interface.py", line 761, in publish_output_raw
    self._publish_output_raw(o)
  File "C:\ProgramData\anaconda3\envs\di725-a2-clean\lib\site-packages\wandb\sdk\interface\interface_shared.py", line 38, in _publish_output_raw
    self._publish(rec)
  File "C:\ProgramData\anaconda3\envs\di725-a2-clean\lib\site-packages\wandb\sdk\interface\interface_sock.py", line 39, in _publish
    self._sock_client.send_record_publish(record)
  File "C:\ProgramData\anaconda3\envs\di725-a2-clean\lib\site-packages\wandb\sdk\lib\sock_client.py", line 174, in send_record_publish
    self.send_server_request(server_req)
  File "C:\ProgramData\anaconda3\envs\di725-a2-clean\lib\site-packages\wandb\sdk\lib\sock_client.py", line 154, in send_server_request
    self._send_message(msg)
  File "C:\ProgramData\anaconda3\envs\di725-a2-clean\lib\site-packages\wandb\sdk\lib\sock_client.py", line 151, in _send_message
    self._sendall_with_error_handle(header + data)
  File "C:\ProgramData\anaconda3\envs\di725-a2-clean\lib\site-packages\wandb\sdk\lib\sock_client.py", line 130, in _sendall_with_error_handle
    sent = self._sock.send(data)
ConnectionResetError: [WinError 10054] An existing connection was forcibly closed by the remote host
2025-04-20 20:19:03,810 ERROR   MainThread:1988 [redirect.py:_on_write():661] [no run ID] error in stderr callback
Traceback (most recent call last):
  File "C:\ProgramData\anaconda3\envs\di725-a2-clean\lib\site-packages\wandb\sdk\lib\redirect.py", line 659, in _on_write
    cb(written_data)
  File "C:\ProgramData\anaconda3\envs\di725-a2-clean\lib\site-packages\wandb\sdk\wandb_run.py", line 2381, in <lambda>
    lambda data: self._console_raw_callback("stderr", data),
  File "C:\ProgramData\anaconda3\envs\di725-a2-clean\lib\site-packages\wandb\sdk\wandb_run.py", line 387, in wrapper
    return func(self, *args, **kwargs)
  File "C:\ProgramData\anaconda3\envs\di725-a2-clean\lib\site-packages\wandb\sdk\wandb_run.py", line 435, in wrapper_fn
    return func(self, *args, **kwargs)
  File "C:\ProgramData\anaconda3\envs\di725-a2-clean\lib\site-packages\wandb\sdk\wandb_run.py", line 1518, in _console_raw_callback
    self._backend.interface.publish_output_raw(name, data)
  File "C:\ProgramData\anaconda3\envs\di725-a2-clean\lib\site-packages\wandb\sdk\interface\interface.py", line 761, in publish_output_raw
    self._publish_output_raw(o)
  File "C:\ProgramData\anaconda3\envs\di725-a2-clean\lib\site-packages\wandb\sdk\interface\interface_shared.py", line 38, in _publish_output_raw
    self._publish(rec)
  File "C:\ProgramData\anaconda3\envs\di725-a2-clean\lib\site-packages\wandb\sdk\interface\interface_sock.py", line 39, in _publish
    self._sock_client.send_record_publish(record)
  File "C:\ProgramData\anaconda3\envs\di725-a2-clean\lib\site-packages\wandb\sdk\lib\sock_client.py", line 174, in send_record_publish
    self.send_server_request(server_req)
  File "C:\ProgramData\anaconda3\envs\di725-a2-clean\lib\site-packages\wandb\sdk\lib\sock_client.py", line 154, in send_server_request
    self._send_message(msg)
  File "C:\ProgramData\anaconda3\envs\di725-a2-clean\lib\site-packages\wandb\sdk\lib\sock_client.py", line 151, in _send_message
    self._sendall_with_error_handle(header + data)
  File "C:\ProgramData\anaconda3\envs\di725-a2-clean\lib\site-packages\wandb\sdk\lib\sock_client.py", line 130, in _sendall_with_error_handle
    sent = self._sock.send(data)
ConnectionResetError: [WinError 10054] An existing connection was forcibly closed by the remote host
2025-04-20 20:19:03,811 ERROR   MainThread:1988 [redirect.py:_on_write():661] [no run ID] error in stderr callback
Traceback (most recent call last):
  File "C:\ProgramData\anaconda3\envs\di725-a2-clean\lib\site-packages\wandb\sdk\lib\redirect.py", line 659, in _on_write
    cb(written_data)
  File "C:\ProgramData\anaconda3\envs\di725-a2-clean\lib\site-packages\wandb\sdk\wandb_run.py", line 2381, in <lambda>
    lambda data: self._console_raw_callback("stderr", data),
  File "C:\ProgramData\anaconda3\envs\di725-a2-clean\lib\site-packages\wandb\sdk\wandb_run.py", line 387, in wrapper
    return func(self, *args, **kwargs)
  File "C:\ProgramData\anaconda3\envs\di725-a2-clean\lib\site-packages\wandb\sdk\wandb_run.py", line 435, in wrapper_fn
    return func(self, *args, **kwargs)
  File "C:\ProgramData\anaconda3\envs\di725-a2-clean\lib\site-packages\wandb\sdk\wandb_run.py", line 1518, in _console_raw_callback
    self._backend.interface.publish_output_raw(name, data)
  File "C:\ProgramData\anaconda3\envs\di725-a2-clean\lib\site-packages\wandb\sdk\interface\interface.py", line 761, in publish_output_raw
    self._publish_output_raw(o)
  File "C:\ProgramData\anaconda3\envs\di725-a2-clean\lib\site-packages\wandb\sdk\interface\interface_shared.py", line 38, in _publish_output_raw
    self._publish(rec)
  File "C:\ProgramData\anaconda3\envs\di725-a2-clean\lib\site-packages\wandb\sdk\interface\interface_sock.py", line 39, in _publish
    self._sock_client.send_record_publish(record)
  File "C:\ProgramData\anaconda3\envs\di725-a2-clean\lib\site-packages\wandb\sdk\lib\sock_client.py", line 174, in send_record_publish
    self.send_server_request(server_req)
  File "C:\ProgramData\anaconda3\envs\di725-a2-clean\lib\site-packages\wandb\sdk\lib\sock_client.py", line 154, in send_server_request
    self._send_message(msg)
  File "C:\ProgramData\anaconda3\envs\di725-a2-clean\lib\site-packages\wandb\sdk\lib\sock_client.py", line 151, in _send_message
    self._sendall_with_error_handle(header + data)
  File "C:\ProgramData\anaconda3\envs\di725-a2-clean\lib\site-packages\wandb\sdk\lib\sock_client.py", line 130, in _sendall_with_error_handle
    sent = self._sock.send(data)
ConnectionResetError: [WinError 10054] An existing connection was forcibly closed by the remote host
2025-04-20 20:19:03,812 ERROR   MainThread:1988 [redirect.py:_on_write():661] [no run ID] error in stderr callback
Traceback (most recent call last):
  File "C:\ProgramData\anaconda3\envs\di725-a2-clean\lib\site-packages\wandb\sdk\lib\redirect.py", line 659, in _on_write
    cb(written_data)
  File "C:\ProgramData\anaconda3\envs\di725-a2-clean\lib\site-packages\wandb\sdk\wandb_run.py", line 2381, in <lambda>
    lambda data: self._console_raw_callback("stderr", data),
  File "C:\ProgramData\anaconda3\envs\di725-a2-clean\lib\site-packages\wandb\sdk\wandb_run.py", line 387, in wrapper
    return func(self, *args, **kwargs)
  File "C:\ProgramData\anaconda3\envs\di725-a2-clean\lib\site-packages\wandb\sdk\wandb_run.py", line 435, in wrapper_fn
    return func(self, *args, **kwargs)
  File "C:\ProgramData\anaconda3\envs\di725-a2-clean\lib\site-packages\wandb\sdk\wandb_run.py", line 1518, in _console_raw_callback
    self._backend.interface.publish_output_raw(name, data)
  File "C:\ProgramData\anaconda3\envs\di725-a2-clean\lib\site-packages\wandb\sdk\interface\interface.py", line 761, in publish_output_raw
    self._publish_output_raw(o)
  File "C:\ProgramData\anaconda3\envs\di725-a2-clean\lib\site-packages\wandb\sdk\interface\interface_shared.py", line 38, in _publish_output_raw
    self._publish(rec)
  File "C:\ProgramData\anaconda3\envs\di725-a2-clean\lib\site-packages\wandb\sdk\interface\interface_sock.py", line 39, in _publish
    self._sock_client.send_record_publish(record)
  File "C:\ProgramData\anaconda3\envs\di725-a2-clean\lib\site-packages\wandb\sdk\lib\sock_client.py", line 174, in send_record_publish
    self.send_server_request(server_req)
  File "C:\ProgramData\anaconda3\envs\di725-a2-clean\lib\site-packages\wandb\sdk\lib\sock_client.py", line 154, in send_server_request
    self._send_message(msg)
  File "C:\ProgramData\anaconda3\envs\di725-a2-clean\lib\site-packages\wandb\sdk\lib\sock_client.py", line 151, in _send_message
    self._sendall_with_error_handle(header + data)
  File "C:\ProgramData\anaconda3\envs\di725-a2-clean\lib\site-packages\wandb\sdk\lib\sock_client.py", line 130, in _sendall_with_error_handle
    sent = self._sock.send(data)
ConnectionResetError: [WinError 10054] An existing connection was forcibly closed by the remote host
2025-04-20 20:19:03,813 ERROR   MainThread:1988 [redirect.py:_on_write():661] [no run ID] error in stderr callback
Traceback (most recent call last):
  File "C:\ProgramData\anaconda3\envs\di725-a2-clean\lib\site-packages\wandb\sdk\lib\redirect.py", line 659, in _on_write
    cb(written_data)
  File "C:\ProgramData\anaconda3\envs\di725-a2-clean\lib\site-packages\wandb\sdk\wandb_run.py", line 2381, in <lambda>
    lambda data: self._console_raw_callback("stderr", data),
  File "C:\ProgramData\anaconda3\envs\di725-a2-clean\lib\site-packages\wandb\sdk\wandb_run.py", line 387, in wrapper
    return func(self, *args, **kwargs)
  File "C:\ProgramData\anaconda3\envs\di725-a2-clean\lib\site-packages\wandb\sdk\wandb_run.py", line 435, in wrapper_fn
    return func(self, *args, **kwargs)
  File "C:\ProgramData\anaconda3\envs\di725-a2-clean\lib\site-packages\wandb\sdk\wandb_run.py", line 1518, in _console_raw_callback
    self._backend.interface.publish_output_raw(name, data)
  File "C:\ProgramData\anaconda3\envs\di725-a2-clean\lib\site-packages\wandb\sdk\interface\interface.py", line 761, in publish_output_raw
    self._publish_output_raw(o)
  File "C:\ProgramData\anaconda3\envs\di725-a2-clean\lib\site-packages\wandb\sdk\interface\interface_shared.py", line 38, in _publish_output_raw
    self._publish(rec)
  File "C:\ProgramData\anaconda3\envs\di725-a2-clean\lib\site-packages\wandb\sdk\interface\interface_sock.py", line 39, in _publish
    self._sock_client.send_record_publish(record)
  File "C:\ProgramData\anaconda3\envs\di725-a2-clean\lib\site-packages\wandb\sdk\lib\sock_client.py", line 174, in send_record_publish
    self.send_server_request(server_req)
  File "C:\ProgramData\anaconda3\envs\di725-a2-clean\lib\site-packages\wandb\sdk\lib\sock_client.py", line 154, in send_server_request
    self._send_message(msg)
  File "C:\ProgramData\anaconda3\envs\di725-a2-clean\lib\site-packages\wandb\sdk\lib\sock_client.py", line 151, in _send_message
    self._sendall_with_error_handle(header + data)
  File "C:\ProgramData\anaconda3\envs\di725-a2-clean\lib\site-packages\wandb\sdk\lib\sock_client.py", line 130, in _sendall_with_error_handle
    sent = self._sock.send(data)
ConnectionResetError: [WinError 10054] An existing connection was forcibly closed by the remote host
2025-04-20 20:19:03,814 ERROR   MainThread:1988 [redirect.py:_on_write():661] [no run ID] error in stderr callback
Traceback (most recent call last):
  File "C:\ProgramData\anaconda3\envs\di725-a2-clean\lib\site-packages\wandb\sdk\lib\redirect.py", line 659, in _on_write
    cb(written_data)
  File "C:\ProgramData\anaconda3\envs\di725-a2-clean\lib\site-packages\wandb\sdk\wandb_run.py", line 2381, in <lambda>
    lambda data: self._console_raw_callback("stderr", data),
  File "C:\ProgramData\anaconda3\envs\di725-a2-clean\lib\site-packages\wandb\sdk\wandb_run.py", line 387, in wrapper
    return func(self, *args, **kwargs)
  File "C:\ProgramData\anaconda3\envs\di725-a2-clean\lib\site-packages\wandb\sdk\wandb_run.py", line 435, in wrapper_fn
    return func(self, *args, **kwargs)
  File "C:\ProgramData\anaconda3\envs\di725-a2-clean\lib\site-packages\wandb\sdk\wandb_run.py", line 1518, in _console_raw_callback
    self._backend.interface.publish_output_raw(name, data)
  File "C:\ProgramData\anaconda3\envs\di725-a2-clean\lib\site-packages\wandb\sdk\interface\interface.py", line 761, in publish_output_raw
    self._publish_output_raw(o)
  File "C:\ProgramData\anaconda3\envs\di725-a2-clean\lib\site-packages\wandb\sdk\interface\interface_shared.py", line 38, in _publish_output_raw
    self._publish(rec)
  File "C:\ProgramData\anaconda3\envs\di725-a2-clean\lib\site-packages\wandb\sdk\interface\interface_sock.py", line 39, in _publish
    self._sock_client.send_record_publish(record)
  File "C:\ProgramData\anaconda3\envs\di725-a2-clean\lib\site-packages\wandb\sdk\lib\sock_client.py", line 174, in send_record_publish
    self.send_server_request(server_req)
  File "C:\ProgramData\anaconda3\envs\di725-a2-clean\lib\site-packages\wandb\sdk\lib\sock_client.py", line 154, in send_server_request
    self._send_message(msg)
  File "C:\ProgramData\anaconda3\envs\di725-a2-clean\lib\site-packages\wandb\sdk\lib\sock_client.py", line 151, in _send_message
    self._sendall_with_error_handle(header + data)
  File "C:\ProgramData\anaconda3\envs\di725-a2-clean\lib\site-packages\wandb\sdk\lib\sock_client.py", line 130, in _sendall_with_error_handle
    sent = self._sock.send(data)
ConnectionResetError: [WinError 10054] An existing connection was forcibly closed by the remote host
2025-04-20 20:19:03,815 ERROR   MainThread:1988 [redirect.py:_on_write():661] [no run ID] error in stderr callback
Traceback (most recent call last):
  File "C:\ProgramData\anaconda3\envs\di725-a2-clean\lib\site-packages\wandb\sdk\lib\redirect.py", line 659, in _on_write
    cb(written_data)
  File "C:\ProgramData\anaconda3\envs\di725-a2-clean\lib\site-packages\wandb\sdk\wandb_run.py", line 2381, in <lambda>
    lambda data: self._console_raw_callback("stderr", data),
  File "C:\ProgramData\anaconda3\envs\di725-a2-clean\lib\site-packages\wandb\sdk\wandb_run.py", line 387, in wrapper
    return func(self, *args, **kwargs)
  File "C:\ProgramData\anaconda3\envs\di725-a2-clean\lib\site-packages\wandb\sdk\wandb_run.py", line 435, in wrapper_fn
    return func(self, *args, **kwargs)
  File "C:\ProgramData\anaconda3\envs\di725-a2-clean\lib\site-packages\wandb\sdk\wandb_run.py", line 1518, in _console_raw_callback
    self._backend.interface.publish_output_raw(name, data)
  File "C:\ProgramData\anaconda3\envs\di725-a2-clean\lib\site-packages\wandb\sdk\interface\interface.py", line 761, in publish_output_raw
    self._publish_output_raw(o)
  File "C:\ProgramData\anaconda3\envs\di725-a2-clean\lib\site-packages\wandb\sdk\interface\interface_shared.py", line 38, in _publish_output_raw
    self._publish(rec)
  File "C:\ProgramData\anaconda3\envs\di725-a2-clean\lib\site-packages\wandb\sdk\interface\interface_sock.py", line 39, in _publish
    self._sock_client.send_record_publish(record)
  File "C:\ProgramData\anaconda3\envs\di725-a2-clean\lib\site-packages\wandb\sdk\lib\sock_client.py", line 174, in send_record_publish
    self.send_server_request(server_req)
  File "C:\ProgramData\anaconda3\envs\di725-a2-clean\lib\site-packages\wandb\sdk\lib\sock_client.py", line 154, in send_server_request
    self._send_message(msg)
  File "C:\ProgramData\anaconda3\envs\di725-a2-clean\lib\site-packages\wandb\sdk\lib\sock_client.py", line 151, in _send_message
    self._sendall_with_error_handle(header + data)
  File "C:\ProgramData\anaconda3\envs\di725-a2-clean\lib\site-packages\wandb\sdk\lib\sock_client.py", line 130, in _sendall_with_error_handle
    sent = self._sock.send(data)
ConnectionResetError: [WinError 10054] An existing connection was forcibly closed by the remote host
2025-04-20 20:19:03,816 ERROR   MainThread:1988 [redirect.py:_on_write():661] [no run ID] error in stderr callback
Traceback (most recent call last):
  File "C:\ProgramData\anaconda3\envs\di725-a2-clean\lib\site-packages\wandb\sdk\lib\redirect.py", line 659, in _on_write
    cb(written_data)
  File "C:\ProgramData\anaconda3\envs\di725-a2-clean\lib\site-packages\wandb\sdk\wandb_run.py", line 2381, in <lambda>
    lambda data: self._console_raw_callback("stderr", data),
  File "C:\ProgramData\anaconda3\envs\di725-a2-clean\lib\site-packages\wandb\sdk\wandb_run.py", line 387, in wrapper
    return func(self, *args, **kwargs)
  File "C:\ProgramData\anaconda3\envs\di725-a2-clean\lib\site-packages\wandb\sdk\wandb_run.py", line 435, in wrapper_fn
    return func(self, *args, **kwargs)
  File "C:\ProgramData\anaconda3\envs\di725-a2-clean\lib\site-packages\wandb\sdk\wandb_run.py", line 1518, in _console_raw_callback
    self._backend.interface.publish_output_raw(name, data)
  File "C:\ProgramData\anaconda3\envs\di725-a2-clean\lib\site-packages\wandb\sdk\interface\interface.py", line 761, in publish_output_raw
    self._publish_output_raw(o)
  File "C:\ProgramData\anaconda3\envs\di725-a2-clean\lib\site-packages\wandb\sdk\interface\interface_shared.py", line 38, in _publish_output_raw
    self._publish(rec)
  File "C:\ProgramData\anaconda3\envs\di725-a2-clean\lib\site-packages\wandb\sdk\interface\interface_sock.py", line 39, in _publish
    self._sock_client.send_record_publish(record)
  File "C:\ProgramData\anaconda3\envs\di725-a2-clean\lib\site-packages\wandb\sdk\lib\sock_client.py", line 174, in send_record_publish
    self.send_server_request(server_req)
  File "C:\ProgramData\anaconda3\envs\di725-a2-clean\lib\site-packages\wandb\sdk\lib\sock_client.py", line 154, in send_server_request
    self._send_message(msg)
  File "C:\ProgramData\anaconda3\envs\di725-a2-clean\lib\site-packages\wandb\sdk\lib\sock_client.py", line 151, in _send_message
    self._sendall_with_error_handle(header + data)
  File "C:\ProgramData\anaconda3\envs\di725-a2-clean\lib\site-packages\wandb\sdk\lib\sock_client.py", line 130, in _sendall_with_error_handle
    sent = self._sock.send(data)
ConnectionResetError: [WinError 10054] An existing connection was forcibly closed by the remote host
2025-04-20 20:19:03,817 ERROR   MainThread:1988 [redirect.py:_on_write():661] [no run ID] error in stderr callback
Traceback (most recent call last):
  File "C:\ProgramData\anaconda3\envs\di725-a2-clean\lib\site-packages\wandb\sdk\lib\redirect.py", line 659, in _on_write
    cb(written_data)
  File "C:\ProgramData\anaconda3\envs\di725-a2-clean\lib\site-packages\wandb\sdk\wandb_run.py", line 2381, in <lambda>
    lambda data: self._console_raw_callback("stderr", data),
  File "C:\ProgramData\anaconda3\envs\di725-a2-clean\lib\site-packages\wandb\sdk\wandb_run.py", line 387, in wrapper
    return func(self, *args, **kwargs)
  File "C:\ProgramData\anaconda3\envs\di725-a2-clean\lib\site-packages\wandb\sdk\wandb_run.py", line 435, in wrapper_fn
    return func(self, *args, **kwargs)
  File "C:\ProgramData\anaconda3\envs\di725-a2-clean\lib\site-packages\wandb\sdk\wandb_run.py", line 1518, in _console_raw_callback
    self._backend.interface.publish_output_raw(name, data)
  File "C:\ProgramData\anaconda3\envs\di725-a2-clean\lib\site-packages\wandb\sdk\interface\interface.py", line 761, in publish_output_raw
    self._publish_output_raw(o)
  File "C:\ProgramData\anaconda3\envs\di725-a2-clean\lib\site-packages\wandb\sdk\interface\interface_shared.py", line 38, in _publish_output_raw
    self._publish(rec)
  File "C:\ProgramData\anaconda3\envs\di725-a2-clean\lib\site-packages\wandb\sdk\interface\interface_sock.py", line 39, in _publish
    self._sock_client.send_record_publish(record)
  File "C:\ProgramData\anaconda3\envs\di725-a2-clean\lib\site-packages\wandb\sdk\lib\sock_client.py", line 174, in send_record_publish
    self.send_server_request(server_req)
  File "C:\ProgramData\anaconda3\envs\di725-a2-clean\lib\site-packages\wandb\sdk\lib\sock_client.py", line 154, in send_server_request
    self._send_message(msg)
  File "C:\ProgramData\anaconda3\envs\di725-a2-clean\lib\site-packages\wandb\sdk\lib\sock_client.py", line 151, in _send_message
    self._sendall_with_error_handle(header + data)
  File "C:\ProgramData\anaconda3\envs\di725-a2-clean\lib\site-packages\wandb\sdk\lib\sock_client.py", line 130, in _sendall_with_error_handle
    sent = self._sock.send(data)
ConnectionResetError: [WinError 10054] An existing connection was forcibly closed by the remote host
2025-04-20 20:19:03,818 ERROR   MainThread:1988 [redirect.py:_on_write():661] [no run ID] error in stderr callback
Traceback (most recent call last):
  File "C:\ProgramData\anaconda3\envs\di725-a2-clean\lib\site-packages\wandb\sdk\lib\redirect.py", line 659, in _on_write
    cb(written_data)
  File "C:\ProgramData\anaconda3\envs\di725-a2-clean\lib\site-packages\wandb\sdk\wandb_run.py", line 2381, in <lambda>
    lambda data: self._console_raw_callback("stderr", data),
  File "C:\ProgramData\anaconda3\envs\di725-a2-clean\lib\site-packages\wandb\sdk\wandb_run.py", line 387, in wrapper
    return func(self, *args, **kwargs)
  File "C:\ProgramData\anaconda3\envs\di725-a2-clean\lib\site-packages\wandb\sdk\wandb_run.py", line 435, in wrapper_fn
    return func(self, *args, **kwargs)
  File "C:\ProgramData\anaconda3\envs\di725-a2-clean\lib\site-packages\wandb\sdk\wandb_run.py", line 1518, in _console_raw_callback
    self._backend.interface.publish_output_raw(name, data)
  File "C:\ProgramData\anaconda3\envs\di725-a2-clean\lib\site-packages\wandb\sdk\interface\interface.py", line 761, in publish_output_raw
    self._publish_output_raw(o)
  File "C:\ProgramData\anaconda3\envs\di725-a2-clean\lib\site-packages\wandb\sdk\interface\interface_shared.py", line 38, in _publish_output_raw
    self._publish(rec)
  File "C:\ProgramData\anaconda3\envs\di725-a2-clean\lib\site-packages\wandb\sdk\interface\interface_sock.py", line 39, in _publish
    self._sock_client.send_record_publish(record)
  File "C:\ProgramData\anaconda3\envs\di725-a2-clean\lib\site-packages\wandb\sdk\lib\sock_client.py", line 174, in send_record_publish
    self.send_server_request(server_req)
  File "C:\ProgramData\anaconda3\envs\di725-a2-clean\lib\site-packages\wandb\sdk\lib\sock_client.py", line 154, in send_server_request
    self._send_message(msg)
  File "C:\ProgramData\anaconda3\envs\di725-a2-clean\lib\site-packages\wandb\sdk\lib\sock_client.py", line 151, in _send_message
    self._sendall_with_error_handle(header + data)
  File "C:\ProgramData\anaconda3\envs\di725-a2-clean\lib\site-packages\wandb\sdk\lib\sock_client.py", line 130, in _sendall_with_error_handle
    sent = self._sock.send(data)
ConnectionResetError: [WinError 10054] An existing connection was forcibly closed by the remote host
2025-04-20 20:19:03,819 ERROR   MainThread:1988 [redirect.py:_on_write():661] [no run ID] error in stderr callback
Traceback (most recent call last):
  File "C:\ProgramData\anaconda3\envs\di725-a2-clean\lib\site-packages\wandb\sdk\lib\redirect.py", line 659, in _on_write
    cb(written_data)
  File "C:\ProgramData\anaconda3\envs\di725-a2-clean\lib\site-packages\wandb\sdk\wandb_run.py", line 2381, in <lambda>
    lambda data: self._console_raw_callback("stderr", data),
  File "C:\ProgramData\anaconda3\envs\di725-a2-clean\lib\site-packages\wandb\sdk\wandb_run.py", line 387, in wrapper
    return func(self, *args, **kwargs)
  File "C:\ProgramData\anaconda3\envs\di725-a2-clean\lib\site-packages\wandb\sdk\wandb_run.py", line 435, in wrapper_fn
    return func(self, *args, **kwargs)
  File "C:\ProgramData\anaconda3\envs\di725-a2-clean\lib\site-packages\wandb\sdk\wandb_run.py", line 1518, in _console_raw_callback
    self._backend.interface.publish_output_raw(name, data)
  File "C:\ProgramData\anaconda3\envs\di725-a2-clean\lib\site-packages\wandb\sdk\interface\interface.py", line 761, in publish_output_raw
    self._publish_output_raw(o)
  File "C:\ProgramData\anaconda3\envs\di725-a2-clean\lib\site-packages\wandb\sdk\interface\interface_shared.py", line 38, in _publish_output_raw
    self._publish(rec)
  File "C:\ProgramData\anaconda3\envs\di725-a2-clean\lib\site-packages\wandb\sdk\interface\interface_sock.py", line 39, in _publish
    self._sock_client.send_record_publish(record)
  File "C:\ProgramData\anaconda3\envs\di725-a2-clean\lib\site-packages\wandb\sdk\lib\sock_client.py", line 174, in send_record_publish
    self.send_server_request(server_req)
  File "C:\ProgramData\anaconda3\envs\di725-a2-clean\lib\site-packages\wandb\sdk\lib\sock_client.py", line 154, in send_server_request
    self._send_message(msg)
  File "C:\ProgramData\anaconda3\envs\di725-a2-clean\lib\site-packages\wandb\sdk\lib\sock_client.py", line 151, in _send_message
    self._sendall_with_error_handle(header + data)
  File "C:\ProgramData\anaconda3\envs\di725-a2-clean\lib\site-packages\wandb\sdk\lib\sock_client.py", line 130, in _sendall_with_error_handle
    sent = self._sock.send(data)
ConnectionResetError: [WinError 10054] An existing connection was forcibly closed by the remote host
2025-04-20 20:19:03,820 ERROR   MainThread:1988 [redirect.py:_on_write():661] [no run ID] error in stderr callback
Traceback (most recent call last):
  File "C:\ProgramData\anaconda3\envs\di725-a2-clean\lib\site-packages\wandb\sdk\lib\redirect.py", line 659, in _on_write
    cb(written_data)
  File "C:\ProgramData\anaconda3\envs\di725-a2-clean\lib\site-packages\wandb\sdk\wandb_run.py", line 2381, in <lambda>
    lambda data: self._console_raw_callback("stderr", data),
  File "C:\ProgramData\anaconda3\envs\di725-a2-clean\lib\site-packages\wandb\sdk\wandb_run.py", line 387, in wrapper
    return func(self, *args, **kwargs)
  File "C:\ProgramData\anaconda3\envs\di725-a2-clean\lib\site-packages\wandb\sdk\wandb_run.py", line 435, in wrapper_fn
    return func(self, *args, **kwargs)
  File "C:\ProgramData\anaconda3\envs\di725-a2-clean\lib\site-packages\wandb\sdk\wandb_run.py", line 1518, in _console_raw_callback
    self._backend.interface.publish_output_raw(name, data)
  File "C:\ProgramData\anaconda3\envs\di725-a2-clean\lib\site-packages\wandb\sdk\interface\interface.py", line 761, in publish_output_raw
    self._publish_output_raw(o)
  File "C:\ProgramData\anaconda3\envs\di725-a2-clean\lib\site-packages\wandb\sdk\interface\interface_shared.py", line 38, in _publish_output_raw
    self._publish(rec)
  File "C:\ProgramData\anaconda3\envs\di725-a2-clean\lib\site-packages\wandb\sdk\interface\interface_sock.py", line 39, in _publish
    self._sock_client.send_record_publish(record)
  File "C:\ProgramData\anaconda3\envs\di725-a2-clean\lib\site-packages\wandb\sdk\lib\sock_client.py", line 174, in send_record_publish
    self.send_server_request(server_req)
  File "C:\ProgramData\anaconda3\envs\di725-a2-clean\lib\site-packages\wandb\sdk\lib\sock_client.py", line 154, in send_server_request
    self._send_message(msg)
  File "C:\ProgramData\anaconda3\envs\di725-a2-clean\lib\site-packages\wandb\sdk\lib\sock_client.py", line 151, in _send_message
    self._sendall_with_error_handle(header + data)
  File "C:\ProgramData\anaconda3\envs\di725-a2-clean\lib\site-packages\wandb\sdk\lib\sock_client.py", line 130, in _sendall_with_error_handle
    sent = self._sock.send(data)
ConnectionResetError: [WinError 10054] An existing connection was forcibly closed by the remote host
2025-04-20 20:19:03,821 ERROR   MainThread:1988 [redirect.py:_on_write():661] [no run ID] error in stderr callback
Traceback (most recent call last):
  File "C:\ProgramData\anaconda3\envs\di725-a2-clean\lib\site-packages\wandb\sdk\lib\redirect.py", line 659, in _on_write
    cb(written_data)
  File "C:\ProgramData\anaconda3\envs\di725-a2-clean\lib\site-packages\wandb\sdk\wandb_run.py", line 2381, in <lambda>
    lambda data: self._console_raw_callback("stderr", data),
  File "C:\ProgramData\anaconda3\envs\di725-a2-clean\lib\site-packages\wandb\sdk\wandb_run.py", line 387, in wrapper
    return func(self, *args, **kwargs)
  File "C:\ProgramData\anaconda3\envs\di725-a2-clean\lib\site-packages\wandb\sdk\wandb_run.py", line 435, in wrapper_fn
    return func(self, *args, **kwargs)
  File "C:\ProgramData\anaconda3\envs\di725-a2-clean\lib\site-packages\wandb\sdk\wandb_run.py", line 1518, in _console_raw_callback
    self._backend.interface.publish_output_raw(name, data)
  File "C:\ProgramData\anaconda3\envs\di725-a2-clean\lib\site-packages\wandb\sdk\interface\interface.py", line 761, in publish_output_raw
    self._publish_output_raw(o)
  File "C:\ProgramData\anaconda3\envs\di725-a2-clean\lib\site-packages\wandb\sdk\interface\interface_shared.py", line 38, in _publish_output_raw
    self._publish(rec)
  File "C:\ProgramData\anaconda3\envs\di725-a2-clean\lib\site-packages\wandb\sdk\interface\interface_sock.py", line 39, in _publish
    self._sock_client.send_record_publish(record)
  File "C:\ProgramData\anaconda3\envs\di725-a2-clean\lib\site-packages\wandb\sdk\lib\sock_client.py", line 174, in send_record_publish
    self.send_server_request(server_req)
  File "C:\ProgramData\anaconda3\envs\di725-a2-clean\lib\site-packages\wandb\sdk\lib\sock_client.py", line 154, in send_server_request
    self._send_message(msg)
  File "C:\ProgramData\anaconda3\envs\di725-a2-clean\lib\site-packages\wandb\sdk\lib\sock_client.py", line 151, in _send_message
    self._sendall_with_error_handle(header + data)
  File "C:\ProgramData\anaconda3\envs\di725-a2-clean\lib\site-packages\wandb\sdk\lib\sock_client.py", line 130, in _sendall_with_error_handle
    sent = self._sock.send(data)
ConnectionResetError: [WinError 10054] An existing connection was forcibly closed by the remote host
2025-04-20 20:19:03,822 ERROR   MainThread:1988 [redirect.py:_on_write():661] [no run ID] error in stderr callback
Traceback (most recent call last):
  File "C:\ProgramData\anaconda3\envs\di725-a2-clean\lib\site-packages\wandb\sdk\lib\redirect.py", line 659, in _on_write
    cb(written_data)
  File "C:\ProgramData\anaconda3\envs\di725-a2-clean\lib\site-packages\wandb\sdk\wandb_run.py", line 2381, in <lambda>
    lambda data: self._console_raw_callback("stderr", data),
  File "C:\ProgramData\anaconda3\envs\di725-a2-clean\lib\site-packages\wandb\sdk\wandb_run.py", line 387, in wrapper
    return func(self, *args, **kwargs)
  File "C:\ProgramData\anaconda3\envs\di725-a2-clean\lib\site-packages\wandb\sdk\wandb_run.py", line 435, in wrapper_fn
    return func(self, *args, **kwargs)
  File "C:\ProgramData\anaconda3\envs\di725-a2-clean\lib\site-packages\wandb\sdk\wandb_run.py", line 1518, in _console_raw_callback
    self._backend.interface.publish_output_raw(name, data)
  File "C:\ProgramData\anaconda3\envs\di725-a2-clean\lib\site-packages\wandb\sdk\interface\interface.py", line 761, in publish_output_raw
    self._publish_output_raw(o)
  File "C:\ProgramData\anaconda3\envs\di725-a2-clean\lib\site-packages\wandb\sdk\interface\interface_shared.py", line 38, in _publish_output_raw
    self._publish(rec)
  File "C:\ProgramData\anaconda3\envs\di725-a2-clean\lib\site-packages\wandb\sdk\interface\interface_sock.py", line 39, in _publish
    self._sock_client.send_record_publish(record)
  File "C:\ProgramData\anaconda3\envs\di725-a2-clean\lib\site-packages\wandb\sdk\lib\sock_client.py", line 174, in send_record_publish
    self.send_server_request(server_req)
  File "C:\ProgramData\anaconda3\envs\di725-a2-clean\lib\site-packages\wandb\sdk\lib\sock_client.py", line 154, in send_server_request
    self._send_message(msg)
  File "C:\ProgramData\anaconda3\envs\di725-a2-clean\lib\site-packages\wandb\sdk\lib\sock_client.py", line 151, in _send_message
    self._sendall_with_error_handle(header + data)
  File "C:\ProgramData\anaconda3\envs\di725-a2-clean\lib\site-packages\wandb\sdk\lib\sock_client.py", line 130, in _sendall_with_error_handle
    sent = self._sock.send(data)
ConnectionResetError: [WinError 10054] An existing connection was forcibly closed by the remote host
2025-04-20 20:19:03,823 ERROR   MainThread:1988 [redirect.py:_on_write():661] [no run ID] error in stderr callback
Traceback (most recent call last):
  File "C:\ProgramData\anaconda3\envs\di725-a2-clean\lib\site-packages\wandb\sdk\lib\redirect.py", line 659, in _on_write
    cb(written_data)
  File "C:\ProgramData\anaconda3\envs\di725-a2-clean\lib\site-packages\wandb\sdk\wandb_run.py", line 2381, in <lambda>
    lambda data: self._console_raw_callback("stderr", data),
  File "C:\ProgramData\anaconda3\envs\di725-a2-clean\lib\site-packages\wandb\sdk\wandb_run.py", line 387, in wrapper
    return func(self, *args, **kwargs)
  File "C:\ProgramData\anaconda3\envs\di725-a2-clean\lib\site-packages\wandb\sdk\wandb_run.py", line 435, in wrapper_fn
    return func(self, *args, **kwargs)
  File "C:\ProgramData\anaconda3\envs\di725-a2-clean\lib\site-packages\wandb\sdk\wandb_run.py", line 1518, in _console_raw_callback
    self._backend.interface.publish_output_raw(name, data)
  File "C:\ProgramData\anaconda3\envs\di725-a2-clean\lib\site-packages\wandb\sdk\interface\interface.py", line 761, in publish_output_raw
    self._publish_output_raw(o)
  File "C:\ProgramData\anaconda3\envs\di725-a2-clean\lib\site-packages\wandb\sdk\interface\interface_shared.py", line 38, in _publish_output_raw
    self._publish(rec)
  File "C:\ProgramData\anaconda3\envs\di725-a2-clean\lib\site-packages\wandb\sdk\interface\interface_sock.py", line 39, in _publish
    self._sock_client.send_record_publish(record)
  File "C:\ProgramData\anaconda3\envs\di725-a2-clean\lib\site-packages\wandb\sdk\lib\sock_client.py", line 174, in send_record_publish
    self.send_server_request(server_req)
  File "C:\ProgramData\anaconda3\envs\di725-a2-clean\lib\site-packages\wandb\sdk\lib\sock_client.py", line 154, in send_server_request
    self._send_message(msg)
  File "C:\ProgramData\anaconda3\envs\di725-a2-clean\lib\site-packages\wandb\sdk\lib\sock_client.py", line 151, in _send_message
    self._sendall_with_error_handle(header + data)
  File "C:\ProgramData\anaconda3\envs\di725-a2-clean\lib\site-packages\wandb\sdk\lib\sock_client.py", line 130, in _sendall_with_error_handle
    sent = self._sock.send(data)
ConnectionResetError: [WinError 10054] An existing connection was forcibly closed by the remote host
2025-04-20 20:19:03,824 ERROR   MainThread:1988 [redirect.py:_on_write():661] [no run ID] error in stderr callback
Traceback (most recent call last):
  File "C:\ProgramData\anaconda3\envs\di725-a2-clean\lib\site-packages\wandb\sdk\lib\redirect.py", line 659, in _on_write
    cb(written_data)
  File "C:\ProgramData\anaconda3\envs\di725-a2-clean\lib\site-packages\wandb\sdk\wandb_run.py", line 2381, in <lambda>
    lambda data: self._console_raw_callback("stderr", data),
  File "C:\ProgramData\anaconda3\envs\di725-a2-clean\lib\site-packages\wandb\sdk\wandb_run.py", line 387, in wrapper
    return func(self, *args, **kwargs)
  File "C:\ProgramData\anaconda3\envs\di725-a2-clean\lib\site-packages\wandb\sdk\wandb_run.py", line 435, in wrapper_fn
    return func(self, *args, **kwargs)
  File "C:\ProgramData\anaconda3\envs\di725-a2-clean\lib\site-packages\wandb\sdk\wandb_run.py", line 1518, in _console_raw_callback
    self._backend.interface.publish_output_raw(name, data)
  File "C:\ProgramData\anaconda3\envs\di725-a2-clean\lib\site-packages\wandb\sdk\interface\interface.py", line 761, in publish_output_raw
    self._publish_output_raw(o)
  File "C:\ProgramData\anaconda3\envs\di725-a2-clean\lib\site-packages\wandb\sdk\interface\interface_shared.py", line 38, in _publish_output_raw
    self._publish(rec)
  File "C:\ProgramData\anaconda3\envs\di725-a2-clean\lib\site-packages\wandb\sdk\interface\interface_sock.py", line 39, in _publish
    self._sock_client.send_record_publish(record)
  File "C:\ProgramData\anaconda3\envs\di725-a2-clean\lib\site-packages\wandb\sdk\lib\sock_client.py", line 174, in send_record_publish
    self.send_server_request(server_req)
  File "C:\ProgramData\anaconda3\envs\di725-a2-clean\lib\site-packages\wandb\sdk\lib\sock_client.py", line 154, in send_server_request
    self._send_message(msg)
  File "C:\ProgramData\anaconda3\envs\di725-a2-clean\lib\site-packages\wandb\sdk\lib\sock_client.py", line 151, in _send_message
    self._sendall_with_error_handle(header + data)
  File "C:\ProgramData\anaconda3\envs\di725-a2-clean\lib\site-packages\wandb\sdk\lib\sock_client.py", line 130, in _sendall_with_error_handle
    sent = self._sock.send(data)
ConnectionResetError: [WinError 10054] An existing connection was forcibly closed by the remote host
2025-04-20 20:19:03,825 ERROR   MainThread:1988 [redirect.py:_on_write():661] [no run ID] error in stderr callback
Traceback (most recent call last):
  File "C:\ProgramData\anaconda3\envs\di725-a2-clean\lib\site-packages\wandb\sdk\lib\redirect.py", line 659, in _on_write
    cb(written_data)
  File "C:\ProgramData\anaconda3\envs\di725-a2-clean\lib\site-packages\wandb\sdk\wandb_run.py", line 2381, in <lambda>
    lambda data: self._console_raw_callback("stderr", data),
  File "C:\ProgramData\anaconda3\envs\di725-a2-clean\lib\site-packages\wandb\sdk\wandb_run.py", line 387, in wrapper
    return func(self, *args, **kwargs)
  File "C:\ProgramData\anaconda3\envs\di725-a2-clean\lib\site-packages\wandb\sdk\wandb_run.py", line 435, in wrapper_fn
    return func(self, *args, **kwargs)
  File "C:\ProgramData\anaconda3\envs\di725-a2-clean\lib\site-packages\wandb\sdk\wandb_run.py", line 1518, in _console_raw_callback
    self._backend.interface.publish_output_raw(name, data)
  File "C:\ProgramData\anaconda3\envs\di725-a2-clean\lib\site-packages\wandb\sdk\interface\interface.py", line 761, in publish_output_raw
    self._publish_output_raw(o)
  File "C:\ProgramData\anaconda3\envs\di725-a2-clean\lib\site-packages\wandb\sdk\interface\interface_shared.py", line 38, in _publish_output_raw
    self._publish(rec)
  File "C:\ProgramData\anaconda3\envs\di725-a2-clean\lib\site-packages\wandb\sdk\interface\interface_sock.py", line 39, in _publish
    self._sock_client.send_record_publish(record)
  File "C:\ProgramData\anaconda3\envs\di725-a2-clean\lib\site-packages\wandb\sdk\lib\sock_client.py", line 174, in send_record_publish
    self.send_server_request(server_req)
  File "C:\ProgramData\anaconda3\envs\di725-a2-clean\lib\site-packages\wandb\sdk\lib\sock_client.py", line 154, in send_server_request
    self._send_message(msg)
  File "C:\ProgramData\anaconda3\envs\di725-a2-clean\lib\site-packages\wandb\sdk\lib\sock_client.py", line 151, in _send_message
    self._sendall_with_error_handle(header + data)
  File "C:\ProgramData\anaconda3\envs\di725-a2-clean\lib\site-packages\wandb\sdk\lib\sock_client.py", line 130, in _sendall_with_error_handle
    sent = self._sock.send(data)
ConnectionResetError: [WinError 10054] An existing connection was forcibly closed by the remote host
2025-04-20 20:19:03,826 ERROR   MainThread:1988 [redirect.py:_on_write():661] [no run ID] error in stderr callback
Traceback (most recent call last):
  File "C:\ProgramData\anaconda3\envs\di725-a2-clean\lib\site-packages\wandb\sdk\lib\redirect.py", line 659, in _on_write
    cb(written_data)
  File "C:\ProgramData\anaconda3\envs\di725-a2-clean\lib\site-packages\wandb\sdk\wandb_run.py", line 2381, in <lambda>
    lambda data: self._console_raw_callback("stderr", data),
  File "C:\ProgramData\anaconda3\envs\di725-a2-clean\lib\site-packages\wandb\sdk\wandb_run.py", line 387, in wrapper
    return func(self, *args, **kwargs)
  File "C:\ProgramData\anaconda3\envs\di725-a2-clean\lib\site-packages\wandb\sdk\wandb_run.py", line 435, in wrapper_fn
    return func(self, *args, **kwargs)
  File "C:\ProgramData\anaconda3\envs\di725-a2-clean\lib\site-packages\wandb\sdk\wandb_run.py", line 1518, in _console_raw_callback
    self._backend.interface.publish_output_raw(name, data)
  File "C:\ProgramData\anaconda3\envs\di725-a2-clean\lib\site-packages\wandb\sdk\interface\interface.py", line 761, in publish_output_raw
    self._publish_output_raw(o)
  File "C:\ProgramData\anaconda3\envs\di725-a2-clean\lib\site-packages\wandb\sdk\interface\interface_shared.py", line 38, in _publish_output_raw
    self._publish(rec)
  File "C:\ProgramData\anaconda3\envs\di725-a2-clean\lib\site-packages\wandb\sdk\interface\interface_sock.py", line 39, in _publish
    self._sock_client.send_record_publish(record)
  File "C:\ProgramData\anaconda3\envs\di725-a2-clean\lib\site-packages\wandb\sdk\lib\sock_client.py", line 174, in send_record_publish
    self.send_server_request(server_req)
  File "C:\ProgramData\anaconda3\envs\di725-a2-clean\lib\site-packages\wandb\sdk\lib\sock_client.py", line 154, in send_server_request
    self._send_message(msg)
  File "C:\ProgramData\anaconda3\envs\di725-a2-clean\lib\site-packages\wandb\sdk\lib\sock_client.py", line 151, in _send_message
    self._sendall_with_error_handle(header + data)
  File "C:\ProgramData\anaconda3\envs\di725-a2-clean\lib\site-packages\wandb\sdk\lib\sock_client.py", line 130, in _sendall_with_error_handle
    sent = self._sock.send(data)
ConnectionResetError: [WinError 10054] An existing connection was forcibly closed by the remote host
2025-04-20 20:19:03,827 ERROR   MainThread:1988 [redirect.py:_on_write():661] [no run ID] error in stderr callback
Traceback (most recent call last):
  File "C:\ProgramData\anaconda3\envs\di725-a2-clean\lib\site-packages\wandb\sdk\lib\redirect.py", line 659, in _on_write
    cb(written_data)
  File "C:\ProgramData\anaconda3\envs\di725-a2-clean\lib\site-packages\wandb\sdk\wandb_run.py", line 2381, in <lambda>
    lambda data: self._console_raw_callback("stderr", data),
  File "C:\ProgramData\anaconda3\envs\di725-a2-clean\lib\site-packages\wandb\sdk\wandb_run.py", line 387, in wrapper
    return func(self, *args, **kwargs)
  File "C:\ProgramData\anaconda3\envs\di725-a2-clean\lib\site-packages\wandb\sdk\wandb_run.py", line 435, in wrapper_fn
    return func(self, *args, **kwargs)
  File "C:\ProgramData\anaconda3\envs\di725-a2-clean\lib\site-packages\wandb\sdk\wandb_run.py", line 1518, in _console_raw_callback
    self._backend.interface.publish_output_raw(name, data)
  File "C:\ProgramData\anaconda3\envs\di725-a2-clean\lib\site-packages\wandb\sdk\interface\interface.py", line 761, in publish_output_raw
    self._publish_output_raw(o)
  File "C:\ProgramData\anaconda3\envs\di725-a2-clean\lib\site-packages\wandb\sdk\interface\interface_shared.py", line 38, in _publish_output_raw
    self._publish(rec)
  File "C:\ProgramData\anaconda3\envs\di725-a2-clean\lib\site-packages\wandb\sdk\interface\interface_sock.py", line 39, in _publish
    self._sock_client.send_record_publish(record)
  File "C:\ProgramData\anaconda3\envs\di725-a2-clean\lib\site-packages\wandb\sdk\lib\sock_client.py", line 174, in send_record_publish
    self.send_server_request(server_req)
  File "C:\ProgramData\anaconda3\envs\di725-a2-clean\lib\site-packages\wandb\sdk\lib\sock_client.py", line 154, in send_server_request
    self._send_message(msg)
  File "C:\ProgramData\anaconda3\envs\di725-a2-clean\lib\site-packages\wandb\sdk\lib\sock_client.py", line 151, in _send_message
    self._sendall_with_error_handle(header + data)
  File "C:\ProgramData\anaconda3\envs\di725-a2-clean\lib\site-packages\wandb\sdk\lib\sock_client.py", line 130, in _sendall_with_error_handle
    sent = self._sock.send(data)
ConnectionResetError: [WinError 10054] An existing connection was forcibly closed by the remote host
2025-04-20 20:19:03,827 ERROR   MainThread:1988 [redirect.py:_on_write():661] [no run ID] error in stderr callback
Traceback (most recent call last):
  File "C:\ProgramData\anaconda3\envs\di725-a2-clean\lib\site-packages\wandb\sdk\lib\redirect.py", line 659, in _on_write
    cb(written_data)
  File "C:\ProgramData\anaconda3\envs\di725-a2-clean\lib\site-packages\wandb\sdk\wandb_run.py", line 2381, in <lambda>
    lambda data: self._console_raw_callback("stderr", data),
  File "C:\ProgramData\anaconda3\envs\di725-a2-clean\lib\site-packages\wandb\sdk\wandb_run.py", line 387, in wrapper
    return func(self, *args, **kwargs)
  File "C:\ProgramData\anaconda3\envs\di725-a2-clean\lib\site-packages\wandb\sdk\wandb_run.py", line 435, in wrapper_fn
    return func(self, *args, **kwargs)
  File "C:\ProgramData\anaconda3\envs\di725-a2-clean\lib\site-packages\wandb\sdk\wandb_run.py", line 1518, in _console_raw_callback
    self._backend.interface.publish_output_raw(name, data)
  File "C:\ProgramData\anaconda3\envs\di725-a2-clean\lib\site-packages\wandb\sdk\interface\interface.py", line 761, in publish_output_raw
    self._publish_output_raw(o)
  File "C:\ProgramData\anaconda3\envs\di725-a2-clean\lib\site-packages\wandb\sdk\interface\interface_shared.py", line 38, in _publish_output_raw
    self._publish(rec)
  File "C:\ProgramData\anaconda3\envs\di725-a2-clean\lib\site-packages\wandb\sdk\interface\interface_sock.py", line 39, in _publish
    self._sock_client.send_record_publish(record)
  File "C:\ProgramData\anaconda3\envs\di725-a2-clean\lib\site-packages\wandb\sdk\lib\sock_client.py", line 174, in send_record_publish
    self.send_server_request(server_req)
  File "C:\ProgramData\anaconda3\envs\di725-a2-clean\lib\site-packages\wandb\sdk\lib\sock_client.py", line 154, in send_server_request
    self._send_message(msg)
  File "C:\ProgramData\anaconda3\envs\di725-a2-clean\lib\site-packages\wandb\sdk\lib\sock_client.py", line 151, in _send_message
    self._sendall_with_error_handle(header + data)
  File "C:\ProgramData\anaconda3\envs\di725-a2-clean\lib\site-packages\wandb\sdk\lib\sock_client.py", line 130, in _sendall_with_error_handle
    sent = self._sock.send(data)
ConnectionResetError: [WinError 10054] An existing connection was forcibly closed by the remote host
2025-04-20 20:19:03,827 ERROR   MainThread:1988 [redirect.py:_on_write():661] [no run ID] error in stderr callback
Traceback (most recent call last):
  File "C:\ProgramData\anaconda3\envs\di725-a2-clean\lib\site-packages\wandb\sdk\lib\redirect.py", line 659, in _on_write
    cb(written_data)
  File "C:\ProgramData\anaconda3\envs\di725-a2-clean\lib\site-packages\wandb\sdk\wandb_run.py", line 2381, in <lambda>
    lambda data: self._console_raw_callback("stderr", data),
  File "C:\ProgramData\anaconda3\envs\di725-a2-clean\lib\site-packages\wandb\sdk\wandb_run.py", line 387, in wrapper
    return func(self, *args, **kwargs)
  File "C:\ProgramData\anaconda3\envs\di725-a2-clean\lib\site-packages\wandb\sdk\wandb_run.py", line 435, in wrapper_fn
    return func(self, *args, **kwargs)
  File "C:\ProgramData\anaconda3\envs\di725-a2-clean\lib\site-packages\wandb\sdk\wandb_run.py", line 1518, in _console_raw_callback
    self._backend.interface.publish_output_raw(name, data)
  File "C:\ProgramData\anaconda3\envs\di725-a2-clean\lib\site-packages\wandb\sdk\interface\interface.py", line 761, in publish_output_raw
    self._publish_output_raw(o)
  File "C:\ProgramData\anaconda3\envs\di725-a2-clean\lib\site-packages\wandb\sdk\interface\interface_shared.py", line 38, in _publish_output_raw
    self._publish(rec)
  File "C:\ProgramData\anaconda3\envs\di725-a2-clean\lib\site-packages\wandb\sdk\interface\interface_sock.py", line 39, in _publish
    self._sock_client.send_record_publish(record)
  File "C:\ProgramData\anaconda3\envs\di725-a2-clean\lib\site-packages\wandb\sdk\lib\sock_client.py", line 174, in send_record_publish
    self.send_server_request(server_req)
  File "C:\ProgramData\anaconda3\envs\di725-a2-clean\lib\site-packages\wandb\sdk\lib\sock_client.py", line 154, in send_server_request
    self._send_message(msg)
  File "C:\ProgramData\anaconda3\envs\di725-a2-clean\lib\site-packages\wandb\sdk\lib\sock_client.py", line 151, in _send_message
    self._sendall_with_error_handle(header + data)
  File "C:\ProgramData\anaconda3\envs\di725-a2-clean\lib\site-packages\wandb\sdk\lib\sock_client.py", line 130, in _sendall_with_error_handle
    sent = self._sock.send(data)
ConnectionResetError: [WinError 10054] An existing connection was forcibly closed by the remote host
2025-04-20 20:19:03,829 ERROR   MainThread:1988 [redirect.py:_on_write():661] [no run ID] error in stderr callback
Traceback (most recent call last):
  File "C:\ProgramData\anaconda3\envs\di725-a2-clean\lib\site-packages\wandb\sdk\lib\redirect.py", line 659, in _on_write
    cb(written_data)
  File "C:\ProgramData\anaconda3\envs\di725-a2-clean\lib\site-packages\wandb\sdk\wandb_run.py", line 2381, in <lambda>
    lambda data: self._console_raw_callback("stderr", data),
  File "C:\ProgramData\anaconda3\envs\di725-a2-clean\lib\site-packages\wandb\sdk\wandb_run.py", line 387, in wrapper
    return func(self, *args, **kwargs)
  File "C:\ProgramData\anaconda3\envs\di725-a2-clean\lib\site-packages\wandb\sdk\wandb_run.py", line 435, in wrapper_fn
    return func(self, *args, **kwargs)
  File "C:\ProgramData\anaconda3\envs\di725-a2-clean\lib\site-packages\wandb\sdk\wandb_run.py", line 1518, in _console_raw_callback
    self._backend.interface.publish_output_raw(name, data)
  File "C:\ProgramData\anaconda3\envs\di725-a2-clean\lib\site-packages\wandb\sdk\interface\interface.py", line 761, in publish_output_raw
    self._publish_output_raw(o)
  File "C:\ProgramData\anaconda3\envs\di725-a2-clean\lib\site-packages\wandb\sdk\interface\interface_shared.py", line 38, in _publish_output_raw
    self._publish(rec)
  File "C:\ProgramData\anaconda3\envs\di725-a2-clean\lib\site-packages\wandb\sdk\interface\interface_sock.py", line 39, in _publish
    self._sock_client.send_record_publish(record)
  File "C:\ProgramData\anaconda3\envs\di725-a2-clean\lib\site-packages\wandb\sdk\lib\sock_client.py", line 174, in send_record_publish
    self.send_server_request(server_req)
  File "C:\ProgramData\anaconda3\envs\di725-a2-clean\lib\site-packages\wandb\sdk\lib\sock_client.py", line 154, in send_server_request
    self._send_message(msg)
  File "C:\ProgramData\anaconda3\envs\di725-a2-clean\lib\site-packages\wandb\sdk\lib\sock_client.py", line 151, in _send_message
    self._sendall_with_error_handle(header + data)
  File "C:\ProgramData\anaconda3\envs\di725-a2-clean\lib\site-packages\wandb\sdk\lib\sock_client.py", line 130, in _sendall_with_error_handle
    sent = self._sock.send(data)
ConnectionResetError: [WinError 10054] An existing connection was forcibly closed by the remote host
2025-04-20 20:19:03,829 ERROR   MainThread:1988 [redirect.py:_on_write():661] [no run ID] error in stderr callback
Traceback (most recent call last):
  File "C:\ProgramData\anaconda3\envs\di725-a2-clean\lib\site-packages\wandb\sdk\lib\redirect.py", line 659, in _on_write
    cb(written_data)
  File "C:\ProgramData\anaconda3\envs\di725-a2-clean\lib\site-packages\wandb\sdk\wandb_run.py", line 2381, in <lambda>
    lambda data: self._console_raw_callback("stderr", data),
  File "C:\ProgramData\anaconda3\envs\di725-a2-clean\lib\site-packages\wandb\sdk\wandb_run.py", line 387, in wrapper
    return func(self, *args, **kwargs)
  File "C:\ProgramData\anaconda3\envs\di725-a2-clean\lib\site-packages\wandb\sdk\wandb_run.py", line 435, in wrapper_fn
    return func(self, *args, **kwargs)
  File "C:\ProgramData\anaconda3\envs\di725-a2-clean\lib\site-packages\wandb\sdk\wandb_run.py", line 1518, in _console_raw_callback
    self._backend.interface.publish_output_raw(name, data)
  File "C:\ProgramData\anaconda3\envs\di725-a2-clean\lib\site-packages\wandb\sdk\interface\interface.py", line 761, in publish_output_raw
    self._publish_output_raw(o)
  File "C:\ProgramData\anaconda3\envs\di725-a2-clean\lib\site-packages\wandb\sdk\interface\interface_shared.py", line 38, in _publish_output_raw
    self._publish(rec)
  File "C:\ProgramData\anaconda3\envs\di725-a2-clean\lib\site-packages\wandb\sdk\interface\interface_sock.py", line 39, in _publish
    self._sock_client.send_record_publish(record)
  File "C:\ProgramData\anaconda3\envs\di725-a2-clean\lib\site-packages\wandb\sdk\lib\sock_client.py", line 174, in send_record_publish
    self.send_server_request(server_req)
  File "C:\ProgramData\anaconda3\envs\di725-a2-clean\lib\site-packages\wandb\sdk\lib\sock_client.py", line 154, in send_server_request
    self._send_message(msg)
  File "C:\ProgramData\anaconda3\envs\di725-a2-clean\lib\site-packages\wandb\sdk\lib\sock_client.py", line 151, in _send_message
    self._sendall_with_error_handle(header + data)
  File "C:\ProgramData\anaconda3\envs\di725-a2-clean\lib\site-packages\wandb\sdk\lib\sock_client.py", line 130, in _sendall_with_error_handle
    sent = self._sock.send(data)
ConnectionResetError: [WinError 10054] An existing connection was forcibly closed by the remote host
2025-04-20 20:19:03,830 ERROR   MainThread:1988 [redirect.py:_on_write():661] [no run ID] error in stderr callback
Traceback (most recent call last):
  File "C:\ProgramData\anaconda3\envs\di725-a2-clean\lib\site-packages\wandb\sdk\lib\redirect.py", line 659, in _on_write
    cb(written_data)
  File "C:\ProgramData\anaconda3\envs\di725-a2-clean\lib\site-packages\wandb\sdk\wandb_run.py", line 2381, in <lambda>
    lambda data: self._console_raw_callback("stderr", data),
  File "C:\ProgramData\anaconda3\envs\di725-a2-clean\lib\site-packages\wandb\sdk\wandb_run.py", line 387, in wrapper
    return func(self, *args, **kwargs)
  File "C:\ProgramData\anaconda3\envs\di725-a2-clean\lib\site-packages\wandb\sdk\wandb_run.py", line 435, in wrapper_fn
    return func(self, *args, **kwargs)
  File "C:\ProgramData\anaconda3\envs\di725-a2-clean\lib\site-packages\wandb\sdk\wandb_run.py", line 1518, in _console_raw_callback
    self._backend.interface.publish_output_raw(name, data)
  File "C:\ProgramData\anaconda3\envs\di725-a2-clean\lib\site-packages\wandb\sdk\interface\interface.py", line 761, in publish_output_raw
    self._publish_output_raw(o)
  File "C:\ProgramData\anaconda3\envs\di725-a2-clean\lib\site-packages\wandb\sdk\interface\interface_shared.py", line 38, in _publish_output_raw
    self._publish(rec)
  File "C:\ProgramData\anaconda3\envs\di725-a2-clean\lib\site-packages\wandb\sdk\interface\interface_sock.py", line 39, in _publish
    self._sock_client.send_record_publish(record)
  File "C:\ProgramData\anaconda3\envs\di725-a2-clean\lib\site-packages\wandb\sdk\lib\sock_client.py", line 174, in send_record_publish
    self.send_server_request(server_req)
  File "C:\ProgramData\anaconda3\envs\di725-a2-clean\lib\site-packages\wandb\sdk\lib\sock_client.py", line 154, in send_server_request
    self._send_message(msg)
  File "C:\ProgramData\anaconda3\envs\di725-a2-clean\lib\site-packages\wandb\sdk\lib\sock_client.py", line 151, in _send_message
    self._sendall_with_error_handle(header + data)
  File "C:\ProgramData\anaconda3\envs\di725-a2-clean\lib\site-packages\wandb\sdk\lib\sock_client.py", line 130, in _sendall_with_error_handle
    sent = self._sock.send(data)
ConnectionResetError: [WinError 10054] An existing connection was forcibly closed by the remote host
2025-04-20 20:19:03,831 ERROR   MainThread:1988 [redirect.py:_on_write():661] [no run ID] error in stderr callback
Traceback (most recent call last):
  File "C:\ProgramData\anaconda3\envs\di725-a2-clean\lib\site-packages\wandb\sdk\lib\redirect.py", line 659, in _on_write
    cb(written_data)
  File "C:\ProgramData\anaconda3\envs\di725-a2-clean\lib\site-packages\wandb\sdk\wandb_run.py", line 2381, in <lambda>
    lambda data: self._console_raw_callback("stderr", data),
  File "C:\ProgramData\anaconda3\envs\di725-a2-clean\lib\site-packages\wandb\sdk\wandb_run.py", line 387, in wrapper
    return func(self, *args, **kwargs)
  File "C:\ProgramData\anaconda3\envs\di725-a2-clean\lib\site-packages\wandb\sdk\wandb_run.py", line 435, in wrapper_fn
    return func(self, *args, **kwargs)
  File "C:\ProgramData\anaconda3\envs\di725-a2-clean\lib\site-packages\wandb\sdk\wandb_run.py", line 1518, in _console_raw_callback
    self._backend.interface.publish_output_raw(name, data)
  File "C:\ProgramData\anaconda3\envs\di725-a2-clean\lib\site-packages\wandb\sdk\interface\interface.py", line 761, in publish_output_raw
    self._publish_output_raw(o)
  File "C:\ProgramData\anaconda3\envs\di725-a2-clean\lib\site-packages\wandb\sdk\interface\interface_shared.py", line 38, in _publish_output_raw
    self._publish(rec)
  File "C:\ProgramData\anaconda3\envs\di725-a2-clean\lib\site-packages\wandb\sdk\interface\interface_sock.py", line 39, in _publish
    self._sock_client.send_record_publish(record)
  File "C:\ProgramData\anaconda3\envs\di725-a2-clean\lib\site-packages\wandb\sdk\lib\sock_client.py", line 174, in send_record_publish
    self.send_server_request(server_req)
  File "C:\ProgramData\anaconda3\envs\di725-a2-clean\lib\site-packages\wandb\sdk\lib\sock_client.py", line 154, in send_server_request
    self._send_message(msg)
  File "C:\ProgramData\anaconda3\envs\di725-a2-clean\lib\site-packages\wandb\sdk\lib\sock_client.py", line 151, in _send_message
    self._sendall_with_error_handle(header + data)
  File "C:\ProgramData\anaconda3\envs\di725-a2-clean\lib\site-packages\wandb\sdk\lib\sock_client.py", line 130, in _sendall_with_error_handle
    sent = self._sock.send(data)
ConnectionResetError: [WinError 10054] An existing connection was forcibly closed by the remote host
2025-04-20 20:19:03,832 ERROR   MainThread:1988 [redirect.py:_on_write():661] [no run ID] error in stderr callback
Traceback (most recent call last):
  File "C:\ProgramData\anaconda3\envs\di725-a2-clean\lib\site-packages\wandb\sdk\lib\redirect.py", line 659, in _on_write
    cb(written_data)
  File "C:\ProgramData\anaconda3\envs\di725-a2-clean\lib\site-packages\wandb\sdk\wandb_run.py", line 2381, in <lambda>
    lambda data: self._console_raw_callback("stderr", data),
  File "C:\ProgramData\anaconda3\envs\di725-a2-clean\lib\site-packages\wandb\sdk\wandb_run.py", line 387, in wrapper
    return func(self, *args, **kwargs)
  File "C:\ProgramData\anaconda3\envs\di725-a2-clean\lib\site-packages\wandb\sdk\wandb_run.py", line 435, in wrapper_fn
    return func(self, *args, **kwargs)
  File "C:\ProgramData\anaconda3\envs\di725-a2-clean\lib\site-packages\wandb\sdk\wandb_run.py", line 1518, in _console_raw_callback
    self._backend.interface.publish_output_raw(name, data)
  File "C:\ProgramData\anaconda3\envs\di725-a2-clean\lib\site-packages\wandb\sdk\interface\interface.py", line 761, in publish_output_raw
    self._publish_output_raw(o)
  File "C:\ProgramData\anaconda3\envs\di725-a2-clean\lib\site-packages\wandb\sdk\interface\interface_shared.py", line 38, in _publish_output_raw
    self._publish(rec)
  File "C:\ProgramData\anaconda3\envs\di725-a2-clean\lib\site-packages\wandb\sdk\interface\interface_sock.py", line 39, in _publish
    self._sock_client.send_record_publish(record)
  File "C:\ProgramData\anaconda3\envs\di725-a2-clean\lib\site-packages\wandb\sdk\lib\sock_client.py", line 174, in send_record_publish
    self.send_server_request(server_req)
  File "C:\ProgramData\anaconda3\envs\di725-a2-clean\lib\site-packages\wandb\sdk\lib\sock_client.py", line 154, in send_server_request
    self._send_message(msg)
  File "C:\ProgramData\anaconda3\envs\di725-a2-clean\lib\site-packages\wandb\sdk\lib\sock_client.py", line 151, in _send_message
    self._sendall_with_error_handle(header + data)
  File "C:\ProgramData\anaconda3\envs\di725-a2-clean\lib\site-packages\wandb\sdk\lib\sock_client.py", line 130, in _sendall_with_error_handle
    sent = self._sock.send(data)
ConnectionResetError: [WinError 10054] An existing connection was forcibly closed by the remote host
2025-04-20 20:19:03,833 ERROR   MainThread:1988 [redirect.py:_on_write():661] [no run ID] error in stderr callback
Traceback (most recent call last):
  File "C:\ProgramData\anaconda3\envs\di725-a2-clean\lib\site-packages\wandb\sdk\lib\redirect.py", line 659, in _on_write
    cb(written_data)
  File "C:\ProgramData\anaconda3\envs\di725-a2-clean\lib\site-packages\wandb\sdk\wandb_run.py", line 2381, in <lambda>
    lambda data: self._console_raw_callback("stderr", data),
  File "C:\ProgramData\anaconda3\envs\di725-a2-clean\lib\site-packages\wandb\sdk\wandb_run.py", line 387, in wrapper
    return func(self, *args, **kwargs)
  File "C:\ProgramData\anaconda3\envs\di725-a2-clean\lib\site-packages\wandb\sdk\wandb_run.py", line 435, in wrapper_fn
    return func(self, *args, **kwargs)
  File "C:\ProgramData\anaconda3\envs\di725-a2-clean\lib\site-packages\wandb\sdk\wandb_run.py", line 1518, in _console_raw_callback
    self._backend.interface.publish_output_raw(name, data)
  File "C:\ProgramData\anaconda3\envs\di725-a2-clean\lib\site-packages\wandb\sdk\interface\interface.py", line 761, in publish_output_raw
    self._publish_output_raw(o)
  File "C:\ProgramData\anaconda3\envs\di725-a2-clean\lib\site-packages\wandb\sdk\interface\interface_shared.py", line 38, in _publish_output_raw
    self._publish(rec)
  File "C:\ProgramData\anaconda3\envs\di725-a2-clean\lib\site-packages\wandb\sdk\interface\interface_sock.py", line 39, in _publish
    self._sock_client.send_record_publish(record)
  File "C:\ProgramData\anaconda3\envs\di725-a2-clean\lib\site-packages\wandb\sdk\lib\sock_client.py", line 174, in send_record_publish
    self.send_server_request(server_req)
  File "C:\ProgramData\anaconda3\envs\di725-a2-clean\lib\site-packages\wandb\sdk\lib\sock_client.py", line 154, in send_server_request
    self._send_message(msg)
  File "C:\ProgramData\anaconda3\envs\di725-a2-clean\lib\site-packages\wandb\sdk\lib\sock_client.py", line 151, in _send_message
    self._sendall_with_error_handle(header + data)
  File "C:\ProgramData\anaconda3\envs\di725-a2-clean\lib\site-packages\wandb\sdk\lib\sock_client.py", line 130, in _sendall_with_error_handle
    sent = self._sock.send(data)
ConnectionResetError: [WinError 10054] An existing connection was forcibly closed by the remote host
2025-04-20 20:19:03,834 ERROR   MainThread:1988 [redirect.py:_on_write():661] [no run ID] error in stderr callback
Traceback (most recent call last):
  File "C:\ProgramData\anaconda3\envs\di725-a2-clean\lib\site-packages\wandb\sdk\lib\redirect.py", line 659, in _on_write
    cb(written_data)
  File "C:\ProgramData\anaconda3\envs\di725-a2-clean\lib\site-packages\wandb\sdk\wandb_run.py", line 2381, in <lambda>
    lambda data: self._console_raw_callback("stderr", data),
  File "C:\ProgramData\anaconda3\envs\di725-a2-clean\lib\site-packages\wandb\sdk\wandb_run.py", line 387, in wrapper
    return func(self, *args, **kwargs)
  File "C:\ProgramData\anaconda3\envs\di725-a2-clean\lib\site-packages\wandb\sdk\wandb_run.py", line 435, in wrapper_fn
    return func(self, *args, **kwargs)
  File "C:\ProgramData\anaconda3\envs\di725-a2-clean\lib\site-packages\wandb\sdk\wandb_run.py", line 1518, in _console_raw_callback
    self._backend.interface.publish_output_raw(name, data)
  File "C:\ProgramData\anaconda3\envs\di725-a2-clean\lib\site-packages\wandb\sdk\interface\interface.py", line 761, in publish_output_raw
    self._publish_output_raw(o)
  File "C:\ProgramData\anaconda3\envs\di725-a2-clean\lib\site-packages\wandb\sdk\interface\interface_shared.py", line 38, in _publish_output_raw
    self._publish(rec)
  File "C:\ProgramData\anaconda3\envs\di725-a2-clean\lib\site-packages\wandb\sdk\interface\interface_sock.py", line 39, in _publish
    self._sock_client.send_record_publish(record)
  File "C:\ProgramData\anaconda3\envs\di725-a2-clean\lib\site-packages\wandb\sdk\lib\sock_client.py", line 174, in send_record_publish
    self.send_server_request(server_req)
  File "C:\ProgramData\anaconda3\envs\di725-a2-clean\lib\site-packages\wandb\sdk\lib\sock_client.py", line 154, in send_server_request
    self._send_message(msg)
  File "C:\ProgramData\anaconda3\envs\di725-a2-clean\lib\site-packages\wandb\sdk\lib\sock_client.py", line 151, in _send_message
    self._sendall_with_error_handle(header + data)
  File "C:\ProgramData\anaconda3\envs\di725-a2-clean\lib\site-packages\wandb\sdk\lib\sock_client.py", line 130, in _sendall_with_error_handle
    sent = self._sock.send(data)
ConnectionResetError: [WinError 10054] An existing connection was forcibly closed by the remote host
