2025-04-20 20:13:53,851 INFO    MainThread:27936 [wandb_setup.py:_flush():67] Current SDK version is 0.19.9
2025-04-20 20:13:53,851 INFO    MainThread:27936 [wandb_setup.py:_flush():67] Configure stats pid to 27936
2025-04-20 20:13:53,852 INFO    MainThread:27936 [wandb_setup.py:_flush():67] Loading settings from C:\Users\Administrator\.config\wandb\settings
2025-04-20 20:13:53,852 INFO    MainThread:27936 [wandb_setup.py:_flush():67] Loading settings from C:\Users\Administrator\Desktop\di725-term-project\di725-project\notebooks\wandb\settings
2025-04-20 20:13:53,852 INFO    MainThread:27936 [wandb_setup.py:_flush():67] Loading settings from environment variables
2025-04-20 20:13:53,852 INFO    MainThread:27936 [wandb_init.py:setup_run_log_directory():662] Logging user logs to C:\Users\Administrator\Desktop\di725-term-project\di725-project\notebooks\wandb\run-20250420_201353-0v3736du\logs\debug.log
2025-04-20 20:13:53,862 INFO    MainThread:27936 [wandb_init.py:setup_run_log_directory():663] Logging internal logs to C:\Users\Administrator\Desktop\di725-term-project\di725-project\notebooks\wandb\run-20250420_201353-0v3736du\logs\debug-internal.log
2025-04-20 20:13:53,862 INFO    MainThread:27936 [wandb_init.py:monkeypatch_ipython():581] configuring jupyter hooks <wandb.sdk.wandb_init._WandbInit object at 0x000001C378B1DBA0>
2025-04-20 20:13:53,862 INFO    MainThread:27936 [wandb_init.py:init():781] calling init triggers
2025-04-20 20:13:53,862 INFO    MainThread:27936 [wandb_init.py:init():786] wandb.init called with sweep_config: {}
config: {'_wandb': {}}
2025-04-20 20:13:53,862 INFO    MainThread:27936 [wandb_init.py:init():809] starting backend
2025-04-20 20:13:53,862 INFO    MainThread:27936 [wandb_init.py:init():813] sending inform_init request
2025-04-20 20:13:53,872 INFO    MainThread:27936 [backend.py:_multiprocessing_setup():101] multiprocessing start_methods=spawn, using: spawn
2025-04-20 20:13:53,873 INFO    MainThread:27936 [wandb_init.py:init():823] backend started and connected
2025-04-20 20:13:53,877 INFO    MainThread:27936 [wandb_run.py:_label_probe_notebook():1267] probe notebook
2025-04-20 20:13:53,879 INFO    MainThread:27936 [wandb_run.py:_label_probe_notebook():1277] Unable to probe notebook: 'NoneType' object has no attribute 'get'
2025-04-20 20:13:53,879 INFO    MainThread:27936 [wandb_init.py:init():915] updated telemetry
2025-04-20 20:13:54,022 INFO    MainThread:27936 [wandb_init.py:init():939] communicating run to backend with 90.0 second timeout
2025-04-20 20:13:54,683 INFO    MainThread:27936 [wandb_init.py:init():1014] starting run threads in backend
2025-04-20 20:13:55,084 INFO    MainThread:27936 [wandb_run.py:_console_start():2454] atexit reg
2025-04-20 20:13:55,085 INFO    MainThread:27936 [wandb_run.py:_redirect():2306] redirect: wrap_raw
2025-04-20 20:13:55,085 INFO    MainThread:27936 [wandb_run.py:_redirect():2371] Wrapping output streams.
2025-04-20 20:13:55,085 INFO    MainThread:27936 [wandb_run.py:_redirect():2394] Redirects installed.
2025-04-20 20:13:55,087 INFO    MainThread:27936 [wandb_init.py:init():1056] run started, returning control to user process
2025-04-20 20:13:55,088 INFO    MainThread:27936 [wandb_run.py:_config_callback():1327] config_cb None None {'task': 'EDA', 'script': 'eda_risc.ipynb', 'dataset': 'RISC', 'date': '2025-04-20'}
2025-04-20 20:13:55,088 INFO    MainThread:27936 [jupyter.py:save_ipynb():384] [no run ID] not saving jupyter notebook
2025-04-20 20:13:55,088 INFO    MainThread:27936 [wandb_init.py:_pause_backend():546] [no run ID] pausing backend
2025-04-20 20:13:57,973 INFO    MainThread:27936 [wandb_init.py:_resume_backend():551] [no run ID] resuming backend
2025-04-20 20:13:58,155 INFO    MainThread:27936 [jupyter.py:save_ipynb():384] [no run ID] not saving jupyter notebook
2025-04-20 20:13:58,155 INFO    MainThread:27936 [wandb_init.py:_pause_backend():546] [no run ID] pausing backend
2025-04-20 20:14:00,799 INFO    MainThread:27936 [wandb_init.py:_resume_backend():551] [no run ID] resuming backend
2025-04-20 20:14:00,809 INFO    MainThread:27936 [jupyter.py:save_ipynb():384] [no run ID] not saving jupyter notebook
2025-04-20 20:14:00,810 INFO    MainThread:27936 [wandb_init.py:_pause_backend():546] [no run ID] pausing backend
2025-04-20 20:14:04,075 INFO    MainThread:27936 [wandb_init.py:_resume_backend():551] [no run ID] resuming backend
2025-04-20 20:14:04,175 INFO    MainThread:27936 [jupyter.py:save_ipynb():384] [no run ID] not saving jupyter notebook
2025-04-20 20:14:04,175 INFO    MainThread:27936 [wandb_init.py:_pause_backend():546] [no run ID] pausing backend
2025-04-20 20:14:05,592 INFO    MainThread:27936 [wandb_init.py:_resume_backend():551] [no run ID] resuming backend
2025-04-20 20:14:05,599 INFO    MainThread:27936 [jupyter.py:save_ipynb():384] [no run ID] not saving jupyter notebook
2025-04-20 20:14:05,599 INFO    MainThread:27936 [wandb_init.py:_pause_backend():546] [no run ID] pausing backend
2025-04-20 20:14:07,765 INFO    MainThread:27936 [wandb_init.py:_resume_backend():551] [no run ID] resuming backend
2025-04-20 20:14:07,847 INFO    MainThread:27936 [jupyter.py:save_ipynb():384] [no run ID] not saving jupyter notebook
2025-04-20 20:14:07,848 INFO    MainThread:27936 [wandb_init.py:_pause_backend():546] [no run ID] pausing backend
2025-04-20 20:14:09,870 INFO    MainThread:27936 [wandb_init.py:_resume_backend():551] [no run ID] resuming backend
2025-04-20 20:14:10,835 INFO    MainThread:27936 [jupyter.py:save_ipynb():384] [no run ID] not saving jupyter notebook
2025-04-20 20:14:10,835 INFO    MainThread:27936 [wandb_init.py:_pause_backend():546] [no run ID] pausing backend
2025-04-20 20:14:15,730 INFO    MainThread:27936 [wandb_init.py:_resume_backend():551] [no run ID] resuming backend
2025-04-20 20:14:17,006 INFO    MainThread:27936 [jupyter.py:save_ipynb():384] [no run ID] not saving jupyter notebook
2025-04-20 20:14:17,006 INFO    MainThread:27936 [wandb_init.py:_pause_backend():546] [no run ID] pausing backend
2025-04-20 20:14:20,939 INFO    MainThread:27936 [wandb_init.py:_resume_backend():551] [no run ID] resuming backend
2025-04-20 20:14:21,501 INFO    MainThread:27936 [jupyter.py:save_ipynb():384] [no run ID] not saving jupyter notebook
2025-04-20 20:14:21,501 INFO    MainThread:27936 [wandb_init.py:_pause_backend():546] [no run ID] pausing backend
2025-04-20 20:17:12,196 WARNING MsgRouterThr:27936 [router.py:message_loop():63] [no run ID] message_loop has been closed
Traceback (most recent call last):
  File "C:\ProgramData\anaconda3\envs\di725-a2-clean\lib\site-packages\wandb\sdk\lib\sock_client.py", line 208, in _read_packet_bytes
    data = self._sock.recv(self._bufsize)
ConnectionResetError: [WinError 10054] An existing connection was forcibly closed by the remote host

The above exception was the direct cause of the following exception:

Traceback (most recent call last):
  File "C:\ProgramData\anaconda3\envs\di725-a2-clean\lib\site-packages\wandb\sdk\interface\router_sock.py", line 27, in _read_message
    return self._sock_client.read_server_response(timeout=1)
  File "C:\ProgramData\anaconda3\envs\di725-a2-clean\lib\site-packages\wandb\sdk\lib\sock_client.py", line 235, in read_server_response
    data = self._read_packet_bytes(timeout=timeout)
  File "C:\ProgramData\anaconda3\envs\di725-a2-clean\lib\site-packages\wandb\sdk\lib\sock_client.py", line 212, in _read_packet_bytes
    raise SockClientClosedError from e
wandb.sdk.lib.sock_client.SockClientClosedError

The above exception was the direct cause of the following exception:

Traceback (most recent call last):
  File "C:\ProgramData\anaconda3\envs\di725-a2-clean\lib\site-packages\wandb\sdk\interface\router.py", line 56, in message_loop
    msg = self._read_message()
  File "C:\ProgramData\anaconda3\envs\di725-a2-clean\lib\site-packages\wandb\sdk\interface\router_sock.py", line 29, in _read_message
    raise MessageRouterClosedError from e
wandb.sdk.interface.router.MessageRouterClosedError
2025-04-20 20:17:12,199 INFO    MsgRouterThr:27936 [mailbox.py:close():129] [no run ID] Closing mailbox, abandoning 1 handles.
2025-04-20 20:17:12,234 ERROR   MainThread:27936 [redirect.py:_on_write():661] [no run ID] error in stderr callback
Traceback (most recent call last):
  File "C:\ProgramData\anaconda3\envs\di725-a2-clean\lib\site-packages\wandb\sdk\lib\redirect.py", line 659, in _on_write
    cb(written_data)
  File "C:\ProgramData\anaconda3\envs\di725-a2-clean\lib\site-packages\wandb\sdk\wandb_run.py", line 2381, in <lambda>
    lambda data: self._console_raw_callback("stderr", data),
  File "C:\ProgramData\anaconda3\envs\di725-a2-clean\lib\site-packages\wandb\sdk\wandb_run.py", line 387, in wrapper
    return func(self, *args, **kwargs)
  File "C:\ProgramData\anaconda3\envs\di725-a2-clean\lib\site-packages\wandb\sdk\wandb_run.py", line 435, in wrapper_fn
    return func(self, *args, **kwargs)
  File "C:\ProgramData\anaconda3\envs\di725-a2-clean\lib\site-packages\wandb\sdk\wandb_run.py", line 1518, in _console_raw_callback
    self._backend.interface.publish_output_raw(name, data)
  File "C:\ProgramData\anaconda3\envs\di725-a2-clean\lib\site-packages\wandb\sdk\interface\interface.py", line 761, in publish_output_raw
    self._publish_output_raw(o)
  File "C:\ProgramData\anaconda3\envs\di725-a2-clean\lib\site-packages\wandb\sdk\interface\interface_shared.py", line 38, in _publish_output_raw
    self._publish(rec)
  File "C:\ProgramData\anaconda3\envs\di725-a2-clean\lib\site-packages\wandb\sdk\interface\interface_sock.py", line 39, in _publish
    self._sock_client.send_record_publish(record)
  File "C:\ProgramData\anaconda3\envs\di725-a2-clean\lib\site-packages\wandb\sdk\lib\sock_client.py", line 174, in send_record_publish
    self.send_server_request(server_req)
  File "C:\ProgramData\anaconda3\envs\di725-a2-clean\lib\site-packages\wandb\sdk\lib\sock_client.py", line 154, in send_server_request
    self._send_message(msg)
  File "C:\ProgramData\anaconda3\envs\di725-a2-clean\lib\site-packages\wandb\sdk\lib\sock_client.py", line 151, in _send_message
    self._sendall_with_error_handle(header + data)
  File "C:\ProgramData\anaconda3\envs\di725-a2-clean\lib\site-packages\wandb\sdk\lib\sock_client.py", line 130, in _sendall_with_error_handle
    sent = self._sock.send(data)
ConnectionResetError: [WinError 10054] An existing connection was forcibly closed by the remote host
2025-04-20 20:17:12,238 ERROR   MainThread:27936 [redirect.py:_on_write():661] [no run ID] error in stderr callback
Traceback (most recent call last):
  File "C:\ProgramData\anaconda3\envs\di725-a2-clean\lib\site-packages\wandb\sdk\lib\redirect.py", line 659, in _on_write
    cb(written_data)
  File "C:\ProgramData\anaconda3\envs\di725-a2-clean\lib\site-packages\wandb\sdk\wandb_run.py", line 2381, in <lambda>
    lambda data: self._console_raw_callback("stderr", data),
  File "C:\ProgramData\anaconda3\envs\di725-a2-clean\lib\site-packages\wandb\sdk\wandb_run.py", line 387, in wrapper
    return func(self, *args, **kwargs)
  File "C:\ProgramData\anaconda3\envs\di725-a2-clean\lib\site-packages\wandb\sdk\wandb_run.py", line 435, in wrapper_fn
    return func(self, *args, **kwargs)
  File "C:\ProgramData\anaconda3\envs\di725-a2-clean\lib\site-packages\wandb\sdk\wandb_run.py", line 1518, in _console_raw_callback
    self._backend.interface.publish_output_raw(name, data)
  File "C:\ProgramData\anaconda3\envs\di725-a2-clean\lib\site-packages\wandb\sdk\interface\interface.py", line 761, in publish_output_raw
    self._publish_output_raw(o)
  File "C:\ProgramData\anaconda3\envs\di725-a2-clean\lib\site-packages\wandb\sdk\interface\interface_shared.py", line 38, in _publish_output_raw
    self._publish(rec)
  File "C:\ProgramData\anaconda3\envs\di725-a2-clean\lib\site-packages\wandb\sdk\interface\interface_sock.py", line 39, in _publish
    self._sock_client.send_record_publish(record)
  File "C:\ProgramData\anaconda3\envs\di725-a2-clean\lib\site-packages\wandb\sdk\lib\sock_client.py", line 174, in send_record_publish
    self.send_server_request(server_req)
  File "C:\ProgramData\anaconda3\envs\di725-a2-clean\lib\site-packages\wandb\sdk\lib\sock_client.py", line 154, in send_server_request
    self._send_message(msg)
  File "C:\ProgramData\anaconda3\envs\di725-a2-clean\lib\site-packages\wandb\sdk\lib\sock_client.py", line 151, in _send_message
    self._sendall_with_error_handle(header + data)
  File "C:\ProgramData\anaconda3\envs\di725-a2-clean\lib\site-packages\wandb\sdk\lib\sock_client.py", line 130, in _sendall_with_error_handle
    sent = self._sock.send(data)
ConnectionResetError: [WinError 10054] An existing connection was forcibly closed by the remote host
2025-04-20 20:17:12,239 ERROR   MainThread:27936 [redirect.py:_on_write():661] [no run ID] error in stderr callback
Traceback (most recent call last):
  File "C:\ProgramData\anaconda3\envs\di725-a2-clean\lib\site-packages\wandb\sdk\lib\redirect.py", line 659, in _on_write
    cb(written_data)
  File "C:\ProgramData\anaconda3\envs\di725-a2-clean\lib\site-packages\wandb\sdk\wandb_run.py", line 2381, in <lambda>
    lambda data: self._console_raw_callback("stderr", data),
  File "C:\ProgramData\anaconda3\envs\di725-a2-clean\lib\site-packages\wandb\sdk\wandb_run.py", line 387, in wrapper
    return func(self, *args, **kwargs)
  File "C:\ProgramData\anaconda3\envs\di725-a2-clean\lib\site-packages\wandb\sdk\wandb_run.py", line 435, in wrapper_fn
    return func(self, *args, **kwargs)
  File "C:\ProgramData\anaconda3\envs\di725-a2-clean\lib\site-packages\wandb\sdk\wandb_run.py", line 1518, in _console_raw_callback
    self._backend.interface.publish_output_raw(name, data)
  File "C:\ProgramData\anaconda3\envs\di725-a2-clean\lib\site-packages\wandb\sdk\interface\interface.py", line 761, in publish_output_raw
    self._publish_output_raw(o)
  File "C:\ProgramData\anaconda3\envs\di725-a2-clean\lib\site-packages\wandb\sdk\interface\interface_shared.py", line 38, in _publish_output_raw
    self._publish(rec)
  File "C:\ProgramData\anaconda3\envs\di725-a2-clean\lib\site-packages\wandb\sdk\interface\interface_sock.py", line 39, in _publish
    self._sock_client.send_record_publish(record)
  File "C:\ProgramData\anaconda3\envs\di725-a2-clean\lib\site-packages\wandb\sdk\lib\sock_client.py", line 174, in send_record_publish
    self.send_server_request(server_req)
  File "C:\ProgramData\anaconda3\envs\di725-a2-clean\lib\site-packages\wandb\sdk\lib\sock_client.py", line 154, in send_server_request
    self._send_message(msg)
  File "C:\ProgramData\anaconda3\envs\di725-a2-clean\lib\site-packages\wandb\sdk\lib\sock_client.py", line 151, in _send_message
    self._sendall_with_error_handle(header + data)
  File "C:\ProgramData\anaconda3\envs\di725-a2-clean\lib\site-packages\wandb\sdk\lib\sock_client.py", line 130, in _sendall_with_error_handle
    sent = self._sock.send(data)
ConnectionResetError: [WinError 10054] An existing connection was forcibly closed by the remote host
2025-04-20 20:17:12,240 ERROR   MainThread:27936 [redirect.py:_on_write():661] [no run ID] error in stderr callback
Traceback (most recent call last):
  File "C:\ProgramData\anaconda3\envs\di725-a2-clean\lib\site-packages\wandb\sdk\lib\redirect.py", line 659, in _on_write
    cb(written_data)
  File "C:\ProgramData\anaconda3\envs\di725-a2-clean\lib\site-packages\wandb\sdk\wandb_run.py", line 2381, in <lambda>
    lambda data: self._console_raw_callback("stderr", data),
  File "C:\ProgramData\anaconda3\envs\di725-a2-clean\lib\site-packages\wandb\sdk\wandb_run.py", line 387, in wrapper
    return func(self, *args, **kwargs)
  File "C:\ProgramData\anaconda3\envs\di725-a2-clean\lib\site-packages\wandb\sdk\wandb_run.py", line 435, in wrapper_fn
    return func(self, *args, **kwargs)
  File "C:\ProgramData\anaconda3\envs\di725-a2-clean\lib\site-packages\wandb\sdk\wandb_run.py", line 1518, in _console_raw_callback
    self._backend.interface.publish_output_raw(name, data)
  File "C:\ProgramData\anaconda3\envs\di725-a2-clean\lib\site-packages\wandb\sdk\interface\interface.py", line 761, in publish_output_raw
    self._publish_output_raw(o)
  File "C:\ProgramData\anaconda3\envs\di725-a2-clean\lib\site-packages\wandb\sdk\interface\interface_shared.py", line 38, in _publish_output_raw
    self._publish(rec)
  File "C:\ProgramData\anaconda3\envs\di725-a2-clean\lib\site-packages\wandb\sdk\interface\interface_sock.py", line 39, in _publish
    self._sock_client.send_record_publish(record)
  File "C:\ProgramData\anaconda3\envs\di725-a2-clean\lib\site-packages\wandb\sdk\lib\sock_client.py", line 174, in send_record_publish
    self.send_server_request(server_req)
  File "C:\ProgramData\anaconda3\envs\di725-a2-clean\lib\site-packages\wandb\sdk\lib\sock_client.py", line 154, in send_server_request
    self._send_message(msg)
  File "C:\ProgramData\anaconda3\envs\di725-a2-clean\lib\site-packages\wandb\sdk\lib\sock_client.py", line 151, in _send_message
    self._sendall_with_error_handle(header + data)
  File "C:\ProgramData\anaconda3\envs\di725-a2-clean\lib\site-packages\wandb\sdk\lib\sock_client.py", line 130, in _sendall_with_error_handle
    sent = self._sock.send(data)
ConnectionResetError: [WinError 10054] An existing connection was forcibly closed by the remote host
2025-04-20 20:17:12,241 ERROR   MainThread:27936 [redirect.py:_on_write():661] [no run ID] error in stderr callback
Traceback (most recent call last):
  File "C:\ProgramData\anaconda3\envs\di725-a2-clean\lib\site-packages\wandb\sdk\lib\redirect.py", line 659, in _on_write
    cb(written_data)
  File "C:\ProgramData\anaconda3\envs\di725-a2-clean\lib\site-packages\wandb\sdk\wandb_run.py", line 2381, in <lambda>
    lambda data: self._console_raw_callback("stderr", data),
  File "C:\ProgramData\anaconda3\envs\di725-a2-clean\lib\site-packages\wandb\sdk\wandb_run.py", line 387, in wrapper
    return func(self, *args, **kwargs)
  File "C:\ProgramData\anaconda3\envs\di725-a2-clean\lib\site-packages\wandb\sdk\wandb_run.py", line 435, in wrapper_fn
    return func(self, *args, **kwargs)
  File "C:\ProgramData\anaconda3\envs\di725-a2-clean\lib\site-packages\wandb\sdk\wandb_run.py", line 1518, in _console_raw_callback
    self._backend.interface.publish_output_raw(name, data)
  File "C:\ProgramData\anaconda3\envs\di725-a2-clean\lib\site-packages\wandb\sdk\interface\interface.py", line 761, in publish_output_raw
    self._publish_output_raw(o)
  File "C:\ProgramData\anaconda3\envs\di725-a2-clean\lib\site-packages\wandb\sdk\interface\interface_shared.py", line 38, in _publish_output_raw
    self._publish(rec)
  File "C:\ProgramData\anaconda3\envs\di725-a2-clean\lib\site-packages\wandb\sdk\interface\interface_sock.py", line 39, in _publish
    self._sock_client.send_record_publish(record)
  File "C:\ProgramData\anaconda3\envs\di725-a2-clean\lib\site-packages\wandb\sdk\lib\sock_client.py", line 174, in send_record_publish
    self.send_server_request(server_req)
  File "C:\ProgramData\anaconda3\envs\di725-a2-clean\lib\site-packages\wandb\sdk\lib\sock_client.py", line 154, in send_server_request
    self._send_message(msg)
  File "C:\ProgramData\anaconda3\envs\di725-a2-clean\lib\site-packages\wandb\sdk\lib\sock_client.py", line 151, in _send_message
    self._sendall_with_error_handle(header + data)
  File "C:\ProgramData\anaconda3\envs\di725-a2-clean\lib\site-packages\wandb\sdk\lib\sock_client.py", line 130, in _sendall_with_error_handle
    sent = self._sock.send(data)
ConnectionResetError: [WinError 10054] An existing connection was forcibly closed by the remote host
2025-04-20 20:17:12,242 ERROR   MainThread:27936 [redirect.py:_on_write():661] [no run ID] error in stderr callback
Traceback (most recent call last):
  File "C:\ProgramData\anaconda3\envs\di725-a2-clean\lib\site-packages\wandb\sdk\lib\redirect.py", line 659, in _on_write
    cb(written_data)
  File "C:\ProgramData\anaconda3\envs\di725-a2-clean\lib\site-packages\wandb\sdk\wandb_run.py", line 2381, in <lambda>
    lambda data: self._console_raw_callback("stderr", data),
  File "C:\ProgramData\anaconda3\envs\di725-a2-clean\lib\site-packages\wandb\sdk\wandb_run.py", line 387, in wrapper
    return func(self, *args, **kwargs)
  File "C:\ProgramData\anaconda3\envs\di725-a2-clean\lib\site-packages\wandb\sdk\wandb_run.py", line 435, in wrapper_fn
    return func(self, *args, **kwargs)
  File "C:\ProgramData\anaconda3\envs\di725-a2-clean\lib\site-packages\wandb\sdk\wandb_run.py", line 1518, in _console_raw_callback
    self._backend.interface.publish_output_raw(name, data)
  File "C:\ProgramData\anaconda3\envs\di725-a2-clean\lib\site-packages\wandb\sdk\interface\interface.py", line 761, in publish_output_raw
    self._publish_output_raw(o)
  File "C:\ProgramData\anaconda3\envs\di725-a2-clean\lib\site-packages\wandb\sdk\interface\interface_shared.py", line 38, in _publish_output_raw
    self._publish(rec)
  File "C:\ProgramData\anaconda3\envs\di725-a2-clean\lib\site-packages\wandb\sdk\interface\interface_sock.py", line 39, in _publish
    self._sock_client.send_record_publish(record)
  File "C:\ProgramData\anaconda3\envs\di725-a2-clean\lib\site-packages\wandb\sdk\lib\sock_client.py", line 174, in send_record_publish
    self.send_server_request(server_req)
  File "C:\ProgramData\anaconda3\envs\di725-a2-clean\lib\site-packages\wandb\sdk\lib\sock_client.py", line 154, in send_server_request
    self._send_message(msg)
  File "C:\ProgramData\anaconda3\envs\di725-a2-clean\lib\site-packages\wandb\sdk\lib\sock_client.py", line 151, in _send_message
    self._sendall_with_error_handle(header + data)
  File "C:\ProgramData\anaconda3\envs\di725-a2-clean\lib\site-packages\wandb\sdk\lib\sock_client.py", line 130, in _sendall_with_error_handle
    sent = self._sock.send(data)
ConnectionResetError: [WinError 10054] An existing connection was forcibly closed by the remote host
2025-04-20 20:17:12,244 ERROR   MainThread:27936 [redirect.py:_on_write():661] [no run ID] error in stderr callback
Traceback (most recent call last):
  File "C:\ProgramData\anaconda3\envs\di725-a2-clean\lib\site-packages\wandb\sdk\lib\redirect.py", line 659, in _on_write
    cb(written_data)
  File "C:\ProgramData\anaconda3\envs\di725-a2-clean\lib\site-packages\wandb\sdk\wandb_run.py", line 2381, in <lambda>
    lambda data: self._console_raw_callback("stderr", data),
  File "C:\ProgramData\anaconda3\envs\di725-a2-clean\lib\site-packages\wandb\sdk\wandb_run.py", line 387, in wrapper
    return func(self, *args, **kwargs)
  File "C:\ProgramData\anaconda3\envs\di725-a2-clean\lib\site-packages\wandb\sdk\wandb_run.py", line 435, in wrapper_fn
    return func(self, *args, **kwargs)
  File "C:\ProgramData\anaconda3\envs\di725-a2-clean\lib\site-packages\wandb\sdk\wandb_run.py", line 1518, in _console_raw_callback
    self._backend.interface.publish_output_raw(name, data)
  File "C:\ProgramData\anaconda3\envs\di725-a2-clean\lib\site-packages\wandb\sdk\interface\interface.py", line 761, in publish_output_raw
    self._publish_output_raw(o)
  File "C:\ProgramData\anaconda3\envs\di725-a2-clean\lib\site-packages\wandb\sdk\interface\interface_shared.py", line 38, in _publish_output_raw
    self._publish(rec)
  File "C:\ProgramData\anaconda3\envs\di725-a2-clean\lib\site-packages\wandb\sdk\interface\interface_sock.py", line 39, in _publish
    self._sock_client.send_record_publish(record)
  File "C:\ProgramData\anaconda3\envs\di725-a2-clean\lib\site-packages\wandb\sdk\lib\sock_client.py", line 174, in send_record_publish
    self.send_server_request(server_req)
  File "C:\ProgramData\anaconda3\envs\di725-a2-clean\lib\site-packages\wandb\sdk\lib\sock_client.py", line 154, in send_server_request
    self._send_message(msg)
  File "C:\ProgramData\anaconda3\envs\di725-a2-clean\lib\site-packages\wandb\sdk\lib\sock_client.py", line 151, in _send_message
    self._sendall_with_error_handle(header + data)
  File "C:\ProgramData\anaconda3\envs\di725-a2-clean\lib\site-packages\wandb\sdk\lib\sock_client.py", line 130, in _sendall_with_error_handle
    sent = self._sock.send(data)
ConnectionResetError: [WinError 10054] An existing connection was forcibly closed by the remote host
2025-04-20 20:17:12,244 ERROR   MainThread:27936 [redirect.py:_on_write():661] [no run ID] error in stderr callback
Traceback (most recent call last):
  File "C:\ProgramData\anaconda3\envs\di725-a2-clean\lib\site-packages\wandb\sdk\lib\redirect.py", line 659, in _on_write
    cb(written_data)
  File "C:\ProgramData\anaconda3\envs\di725-a2-clean\lib\site-packages\wandb\sdk\wandb_run.py", line 2381, in <lambda>
    lambda data: self._console_raw_callback("stderr", data),
  File "C:\ProgramData\anaconda3\envs\di725-a2-clean\lib\site-packages\wandb\sdk\wandb_run.py", line 387, in wrapper
    return func(self, *args, **kwargs)
  File "C:\ProgramData\anaconda3\envs\di725-a2-clean\lib\site-packages\wandb\sdk\wandb_run.py", line 435, in wrapper_fn
    return func(self, *args, **kwargs)
  File "C:\ProgramData\anaconda3\envs\di725-a2-clean\lib\site-packages\wandb\sdk\wandb_run.py", line 1518, in _console_raw_callback
    self._backend.interface.publish_output_raw(name, data)
  File "C:\ProgramData\anaconda3\envs\di725-a2-clean\lib\site-packages\wandb\sdk\interface\interface.py", line 761, in publish_output_raw
    self._publish_output_raw(o)
  File "C:\ProgramData\anaconda3\envs\di725-a2-clean\lib\site-packages\wandb\sdk\interface\interface_shared.py", line 38, in _publish_output_raw
    self._publish(rec)
  File "C:\ProgramData\anaconda3\envs\di725-a2-clean\lib\site-packages\wandb\sdk\interface\interface_sock.py", line 39, in _publish
    self._sock_client.send_record_publish(record)
  File "C:\ProgramData\anaconda3\envs\di725-a2-clean\lib\site-packages\wandb\sdk\lib\sock_client.py", line 174, in send_record_publish
    self.send_server_request(server_req)
  File "C:\ProgramData\anaconda3\envs\di725-a2-clean\lib\site-packages\wandb\sdk\lib\sock_client.py", line 154, in send_server_request
    self._send_message(msg)
  File "C:\ProgramData\anaconda3\envs\di725-a2-clean\lib\site-packages\wandb\sdk\lib\sock_client.py", line 151, in _send_message
    self._sendall_with_error_handle(header + data)
  File "C:\ProgramData\anaconda3\envs\di725-a2-clean\lib\site-packages\wandb\sdk\lib\sock_client.py", line 130, in _sendall_with_error_handle
    sent = self._sock.send(data)
ConnectionResetError: [WinError 10054] An existing connection was forcibly closed by the remote host
2025-04-20 20:17:12,245 ERROR   MainThread:27936 [redirect.py:_on_write():661] [no run ID] error in stderr callback
Traceback (most recent call last):
  File "C:\ProgramData\anaconda3\envs\di725-a2-clean\lib\site-packages\wandb\sdk\lib\redirect.py", line 659, in _on_write
    cb(written_data)
  File "C:\ProgramData\anaconda3\envs\di725-a2-clean\lib\site-packages\wandb\sdk\wandb_run.py", line 2381, in <lambda>
    lambda data: self._console_raw_callback("stderr", data),
  File "C:\ProgramData\anaconda3\envs\di725-a2-clean\lib\site-packages\wandb\sdk\wandb_run.py", line 387, in wrapper
    return func(self, *args, **kwargs)
  File "C:\ProgramData\anaconda3\envs\di725-a2-clean\lib\site-packages\wandb\sdk\wandb_run.py", line 435, in wrapper_fn
    return func(self, *args, **kwargs)
  File "C:\ProgramData\anaconda3\envs\di725-a2-clean\lib\site-packages\wandb\sdk\wandb_run.py", line 1518, in _console_raw_callback
    self._backend.interface.publish_output_raw(name, data)
  File "C:\ProgramData\anaconda3\envs\di725-a2-clean\lib\site-packages\wandb\sdk\interface\interface.py", line 761, in publish_output_raw
    self._publish_output_raw(o)
  File "C:\ProgramData\anaconda3\envs\di725-a2-clean\lib\site-packages\wandb\sdk\interface\interface_shared.py", line 38, in _publish_output_raw
    self._publish(rec)
  File "C:\ProgramData\anaconda3\envs\di725-a2-clean\lib\site-packages\wandb\sdk\interface\interface_sock.py", line 39, in _publish
    self._sock_client.send_record_publish(record)
  File "C:\ProgramData\anaconda3\envs\di725-a2-clean\lib\site-packages\wandb\sdk\lib\sock_client.py", line 174, in send_record_publish
    self.send_server_request(server_req)
  File "C:\ProgramData\anaconda3\envs\di725-a2-clean\lib\site-packages\wandb\sdk\lib\sock_client.py", line 154, in send_server_request
    self._send_message(msg)
  File "C:\ProgramData\anaconda3\envs\di725-a2-clean\lib\site-packages\wandb\sdk\lib\sock_client.py", line 151, in _send_message
    self._sendall_with_error_handle(header + data)
  File "C:\ProgramData\anaconda3\envs\di725-a2-clean\lib\site-packages\wandb\sdk\lib\sock_client.py", line 130, in _sendall_with_error_handle
    sent = self._sock.send(data)
ConnectionResetError: [WinError 10054] An existing connection was forcibly closed by the remote host
2025-04-20 20:17:12,246 ERROR   MainThread:27936 [redirect.py:_on_write():661] [no run ID] error in stderr callback
Traceback (most recent call last):
  File "C:\ProgramData\anaconda3\envs\di725-a2-clean\lib\site-packages\wandb\sdk\lib\redirect.py", line 659, in _on_write
    cb(written_data)
  File "C:\ProgramData\anaconda3\envs\di725-a2-clean\lib\site-packages\wandb\sdk\wandb_run.py", line 2381, in <lambda>
    lambda data: self._console_raw_callback("stderr", data),
  File "C:\ProgramData\anaconda3\envs\di725-a2-clean\lib\site-packages\wandb\sdk\wandb_run.py", line 387, in wrapper
    return func(self, *args, **kwargs)
  File "C:\ProgramData\anaconda3\envs\di725-a2-clean\lib\site-packages\wandb\sdk\wandb_run.py", line 435, in wrapper_fn
    return func(self, *args, **kwargs)
  File "C:\ProgramData\anaconda3\envs\di725-a2-clean\lib\site-packages\wandb\sdk\wandb_run.py", line 1518, in _console_raw_callback
    self._backend.interface.publish_output_raw(name, data)
  File "C:\ProgramData\anaconda3\envs\di725-a2-clean\lib\site-packages\wandb\sdk\interface\interface.py", line 761, in publish_output_raw
    self._publish_output_raw(o)
  File "C:\ProgramData\anaconda3\envs\di725-a2-clean\lib\site-packages\wandb\sdk\interface\interface_shared.py", line 38, in _publish_output_raw
    self._publish(rec)
  File "C:\ProgramData\anaconda3\envs\di725-a2-clean\lib\site-packages\wandb\sdk\interface\interface_sock.py", line 39, in _publish
    self._sock_client.send_record_publish(record)
  File "C:\ProgramData\anaconda3\envs\di725-a2-clean\lib\site-packages\wandb\sdk\lib\sock_client.py", line 174, in send_record_publish
    self.send_server_request(server_req)
  File "C:\ProgramData\anaconda3\envs\di725-a2-clean\lib\site-packages\wandb\sdk\lib\sock_client.py", line 154, in send_server_request
    self._send_message(msg)
  File "C:\ProgramData\anaconda3\envs\di725-a2-clean\lib\site-packages\wandb\sdk\lib\sock_client.py", line 151, in _send_message
    self._sendall_with_error_handle(header + data)
  File "C:\ProgramData\anaconda3\envs\di725-a2-clean\lib\site-packages\wandb\sdk\lib\sock_client.py", line 130, in _sendall_with_error_handle
    sent = self._sock.send(data)
ConnectionResetError: [WinError 10054] An existing connection was forcibly closed by the remote host
2025-04-20 20:17:12,247 ERROR   MainThread:27936 [redirect.py:_on_write():661] [no run ID] error in stderr callback
Traceback (most recent call last):
  File "C:\ProgramData\anaconda3\envs\di725-a2-clean\lib\site-packages\wandb\sdk\lib\redirect.py", line 659, in _on_write
    cb(written_data)
  File "C:\ProgramData\anaconda3\envs\di725-a2-clean\lib\site-packages\wandb\sdk\wandb_run.py", line 2381, in <lambda>
    lambda data: self._console_raw_callback("stderr", data),
  File "C:\ProgramData\anaconda3\envs\di725-a2-clean\lib\site-packages\wandb\sdk\wandb_run.py", line 387, in wrapper
    return func(self, *args, **kwargs)
  File "C:\ProgramData\anaconda3\envs\di725-a2-clean\lib\site-packages\wandb\sdk\wandb_run.py", line 435, in wrapper_fn
    return func(self, *args, **kwargs)
  File "C:\ProgramData\anaconda3\envs\di725-a2-clean\lib\site-packages\wandb\sdk\wandb_run.py", line 1518, in _console_raw_callback
    self._backend.interface.publish_output_raw(name, data)
  File "C:\ProgramData\anaconda3\envs\di725-a2-clean\lib\site-packages\wandb\sdk\interface\interface.py", line 761, in publish_output_raw
    self._publish_output_raw(o)
  File "C:\ProgramData\anaconda3\envs\di725-a2-clean\lib\site-packages\wandb\sdk\interface\interface_shared.py", line 38, in _publish_output_raw
    self._publish(rec)
  File "C:\ProgramData\anaconda3\envs\di725-a2-clean\lib\site-packages\wandb\sdk\interface\interface_sock.py", line 39, in _publish
    self._sock_client.send_record_publish(record)
  File "C:\ProgramData\anaconda3\envs\di725-a2-clean\lib\site-packages\wandb\sdk\lib\sock_client.py", line 174, in send_record_publish
    self.send_server_request(server_req)
  File "C:\ProgramData\anaconda3\envs\di725-a2-clean\lib\site-packages\wandb\sdk\lib\sock_client.py", line 154, in send_server_request
    self._send_message(msg)
  File "C:\ProgramData\anaconda3\envs\di725-a2-clean\lib\site-packages\wandb\sdk\lib\sock_client.py", line 151, in _send_message
    self._sendall_with_error_handle(header + data)
  File "C:\ProgramData\anaconda3\envs\di725-a2-clean\lib\site-packages\wandb\sdk\lib\sock_client.py", line 130, in _sendall_with_error_handle
    sent = self._sock.send(data)
ConnectionResetError: [WinError 10054] An existing connection was forcibly closed by the remote host
2025-04-20 20:17:12,248 ERROR   MainThread:27936 [redirect.py:_on_write():661] [no run ID] error in stderr callback
Traceback (most recent call last):
  File "C:\ProgramData\anaconda3\envs\di725-a2-clean\lib\site-packages\wandb\sdk\lib\redirect.py", line 659, in _on_write
    cb(written_data)
  File "C:\ProgramData\anaconda3\envs\di725-a2-clean\lib\site-packages\wandb\sdk\wandb_run.py", line 2381, in <lambda>
    lambda data: self._console_raw_callback("stderr", data),
  File "C:\ProgramData\anaconda3\envs\di725-a2-clean\lib\site-packages\wandb\sdk\wandb_run.py", line 387, in wrapper
    return func(self, *args, **kwargs)
  File "C:\ProgramData\anaconda3\envs\di725-a2-clean\lib\site-packages\wandb\sdk\wandb_run.py", line 435, in wrapper_fn
    return func(self, *args, **kwargs)
  File "C:\ProgramData\anaconda3\envs\di725-a2-clean\lib\site-packages\wandb\sdk\wandb_run.py", line 1518, in _console_raw_callback
    self._backend.interface.publish_output_raw(name, data)
  File "C:\ProgramData\anaconda3\envs\di725-a2-clean\lib\site-packages\wandb\sdk\interface\interface.py", line 761, in publish_output_raw
    self._publish_output_raw(o)
  File "C:\ProgramData\anaconda3\envs\di725-a2-clean\lib\site-packages\wandb\sdk\interface\interface_shared.py", line 38, in _publish_output_raw
    self._publish(rec)
  File "C:\ProgramData\anaconda3\envs\di725-a2-clean\lib\site-packages\wandb\sdk\interface\interface_sock.py", line 39, in _publish
    self._sock_client.send_record_publish(record)
  File "C:\ProgramData\anaconda3\envs\di725-a2-clean\lib\site-packages\wandb\sdk\lib\sock_client.py", line 174, in send_record_publish
    self.send_server_request(server_req)
  File "C:\ProgramData\anaconda3\envs\di725-a2-clean\lib\site-packages\wandb\sdk\lib\sock_client.py", line 154, in send_server_request
    self._send_message(msg)
  File "C:\ProgramData\anaconda3\envs\di725-a2-clean\lib\site-packages\wandb\sdk\lib\sock_client.py", line 151, in _send_message
    self._sendall_with_error_handle(header + data)
  File "C:\ProgramData\anaconda3\envs\di725-a2-clean\lib\site-packages\wandb\sdk\lib\sock_client.py", line 130, in _sendall_with_error_handle
    sent = self._sock.send(data)
ConnectionResetError: [WinError 10054] An existing connection was forcibly closed by the remote host
2025-04-20 20:17:12,249 ERROR   MainThread:27936 [redirect.py:_on_write():661] [no run ID] error in stderr callback
Traceback (most recent call last):
  File "C:\ProgramData\anaconda3\envs\di725-a2-clean\lib\site-packages\wandb\sdk\lib\redirect.py", line 659, in _on_write
    cb(written_data)
  File "C:\ProgramData\anaconda3\envs\di725-a2-clean\lib\site-packages\wandb\sdk\wandb_run.py", line 2381, in <lambda>
    lambda data: self._console_raw_callback("stderr", data),
  File "C:\ProgramData\anaconda3\envs\di725-a2-clean\lib\site-packages\wandb\sdk\wandb_run.py", line 387, in wrapper
    return func(self, *args, **kwargs)
  File "C:\ProgramData\anaconda3\envs\di725-a2-clean\lib\site-packages\wandb\sdk\wandb_run.py", line 435, in wrapper_fn
    return func(self, *args, **kwargs)
  File "C:\ProgramData\anaconda3\envs\di725-a2-clean\lib\site-packages\wandb\sdk\wandb_run.py", line 1518, in _console_raw_callback
    self._backend.interface.publish_output_raw(name, data)
  File "C:\ProgramData\anaconda3\envs\di725-a2-clean\lib\site-packages\wandb\sdk\interface\interface.py", line 761, in publish_output_raw
    self._publish_output_raw(o)
  File "C:\ProgramData\anaconda3\envs\di725-a2-clean\lib\site-packages\wandb\sdk\interface\interface_shared.py", line 38, in _publish_output_raw
    self._publish(rec)
  File "C:\ProgramData\anaconda3\envs\di725-a2-clean\lib\site-packages\wandb\sdk\interface\interface_sock.py", line 39, in _publish
    self._sock_client.send_record_publish(record)
  File "C:\ProgramData\anaconda3\envs\di725-a2-clean\lib\site-packages\wandb\sdk\lib\sock_client.py", line 174, in send_record_publish
    self.send_server_request(server_req)
  File "C:\ProgramData\anaconda3\envs\di725-a2-clean\lib\site-packages\wandb\sdk\lib\sock_client.py", line 154, in send_server_request
    self._send_message(msg)
  File "C:\ProgramData\anaconda3\envs\di725-a2-clean\lib\site-packages\wandb\sdk\lib\sock_client.py", line 151, in _send_message
    self._sendall_with_error_handle(header + data)
  File "C:\ProgramData\anaconda3\envs\di725-a2-clean\lib\site-packages\wandb\sdk\lib\sock_client.py", line 130, in _sendall_with_error_handle
    sent = self._sock.send(data)
ConnectionResetError: [WinError 10054] An existing connection was forcibly closed by the remote host
2025-04-20 20:17:12,250 ERROR   MainThread:27936 [redirect.py:_on_write():661] [no run ID] error in stderr callback
Traceback (most recent call last):
  File "C:\ProgramData\anaconda3\envs\di725-a2-clean\lib\site-packages\wandb\sdk\lib\redirect.py", line 659, in _on_write
    cb(written_data)
  File "C:\ProgramData\anaconda3\envs\di725-a2-clean\lib\site-packages\wandb\sdk\wandb_run.py", line 2381, in <lambda>
    lambda data: self._console_raw_callback("stderr", data),
  File "C:\ProgramData\anaconda3\envs\di725-a2-clean\lib\site-packages\wandb\sdk\wandb_run.py", line 387, in wrapper
    return func(self, *args, **kwargs)
  File "C:\ProgramData\anaconda3\envs\di725-a2-clean\lib\site-packages\wandb\sdk\wandb_run.py", line 435, in wrapper_fn
    return func(self, *args, **kwargs)
  File "C:\ProgramData\anaconda3\envs\di725-a2-clean\lib\site-packages\wandb\sdk\wandb_run.py", line 1518, in _console_raw_callback
    self._backend.interface.publish_output_raw(name, data)
  File "C:\ProgramData\anaconda3\envs\di725-a2-clean\lib\site-packages\wandb\sdk\interface\interface.py", line 761, in publish_output_raw
    self._publish_output_raw(o)
  File "C:\ProgramData\anaconda3\envs\di725-a2-clean\lib\site-packages\wandb\sdk\interface\interface_shared.py", line 38, in _publish_output_raw
    self._publish(rec)
  File "C:\ProgramData\anaconda3\envs\di725-a2-clean\lib\site-packages\wandb\sdk\interface\interface_sock.py", line 39, in _publish
    self._sock_client.send_record_publish(record)
  File "C:\ProgramData\anaconda3\envs\di725-a2-clean\lib\site-packages\wandb\sdk\lib\sock_client.py", line 174, in send_record_publish
    self.send_server_request(server_req)
  File "C:\ProgramData\anaconda3\envs\di725-a2-clean\lib\site-packages\wandb\sdk\lib\sock_client.py", line 154, in send_server_request
    self._send_message(msg)
  File "C:\ProgramData\anaconda3\envs\di725-a2-clean\lib\site-packages\wandb\sdk\lib\sock_client.py", line 151, in _send_message
    self._sendall_with_error_handle(header + data)
  File "C:\ProgramData\anaconda3\envs\di725-a2-clean\lib\site-packages\wandb\sdk\lib\sock_client.py", line 130, in _sendall_with_error_handle
    sent = self._sock.send(data)
ConnectionResetError: [WinError 10054] An existing connection was forcibly closed by the remote host
2025-04-20 20:17:12,251 ERROR   MainThread:27936 [redirect.py:_on_write():661] [no run ID] error in stderr callback
Traceback (most recent call last):
  File "C:\ProgramData\anaconda3\envs\di725-a2-clean\lib\site-packages\wandb\sdk\lib\redirect.py", line 659, in _on_write
    cb(written_data)
  File "C:\ProgramData\anaconda3\envs\di725-a2-clean\lib\site-packages\wandb\sdk\wandb_run.py", line 2381, in <lambda>
    lambda data: self._console_raw_callback("stderr", data),
  File "C:\ProgramData\anaconda3\envs\di725-a2-clean\lib\site-packages\wandb\sdk\wandb_run.py", line 387, in wrapper
    return func(self, *args, **kwargs)
  File "C:\ProgramData\anaconda3\envs\di725-a2-clean\lib\site-packages\wandb\sdk\wandb_run.py", line 435, in wrapper_fn
    return func(self, *args, **kwargs)
  File "C:\ProgramData\anaconda3\envs\di725-a2-clean\lib\site-packages\wandb\sdk\wandb_run.py", line 1518, in _console_raw_callback
    self._backend.interface.publish_output_raw(name, data)
  File "C:\ProgramData\anaconda3\envs\di725-a2-clean\lib\site-packages\wandb\sdk\interface\interface.py", line 761, in publish_output_raw
    self._publish_output_raw(o)
  File "C:\ProgramData\anaconda3\envs\di725-a2-clean\lib\site-packages\wandb\sdk\interface\interface_shared.py", line 38, in _publish_output_raw
    self._publish(rec)
  File "C:\ProgramData\anaconda3\envs\di725-a2-clean\lib\site-packages\wandb\sdk\interface\interface_sock.py", line 39, in _publish
    self._sock_client.send_record_publish(record)
  File "C:\ProgramData\anaconda3\envs\di725-a2-clean\lib\site-packages\wandb\sdk\lib\sock_client.py", line 174, in send_record_publish
    self.send_server_request(server_req)
  File "C:\ProgramData\anaconda3\envs\di725-a2-clean\lib\site-packages\wandb\sdk\lib\sock_client.py", line 154, in send_server_request
    self._send_message(msg)
  File "C:\ProgramData\anaconda3\envs\di725-a2-clean\lib\site-packages\wandb\sdk\lib\sock_client.py", line 151, in _send_message
    self._sendall_with_error_handle(header + data)
  File "C:\ProgramData\anaconda3\envs\di725-a2-clean\lib\site-packages\wandb\sdk\lib\sock_client.py", line 130, in _sendall_with_error_handle
    sent = self._sock.send(data)
ConnectionResetError: [WinError 10054] An existing connection was forcibly closed by the remote host
2025-04-20 20:17:12,252 ERROR   MainThread:27936 [redirect.py:_on_write():661] [no run ID] error in stderr callback
Traceback (most recent call last):
  File "C:\ProgramData\anaconda3\envs\di725-a2-clean\lib\site-packages\wandb\sdk\lib\redirect.py", line 659, in _on_write
    cb(written_data)
  File "C:\ProgramData\anaconda3\envs\di725-a2-clean\lib\site-packages\wandb\sdk\wandb_run.py", line 2381, in <lambda>
    lambda data: self._console_raw_callback("stderr", data),
  File "C:\ProgramData\anaconda3\envs\di725-a2-clean\lib\site-packages\wandb\sdk\wandb_run.py", line 387, in wrapper
    return func(self, *args, **kwargs)
  File "C:\ProgramData\anaconda3\envs\di725-a2-clean\lib\site-packages\wandb\sdk\wandb_run.py", line 435, in wrapper_fn
    return func(self, *args, **kwargs)
  File "C:\ProgramData\anaconda3\envs\di725-a2-clean\lib\site-packages\wandb\sdk\wandb_run.py", line 1518, in _console_raw_callback
    self._backend.interface.publish_output_raw(name, data)
  File "C:\ProgramData\anaconda3\envs\di725-a2-clean\lib\site-packages\wandb\sdk\interface\interface.py", line 761, in publish_output_raw
    self._publish_output_raw(o)
  File "C:\ProgramData\anaconda3\envs\di725-a2-clean\lib\site-packages\wandb\sdk\interface\interface_shared.py", line 38, in _publish_output_raw
    self._publish(rec)
  File "C:\ProgramData\anaconda3\envs\di725-a2-clean\lib\site-packages\wandb\sdk\interface\interface_sock.py", line 39, in _publish
    self._sock_client.send_record_publish(record)
  File "C:\ProgramData\anaconda3\envs\di725-a2-clean\lib\site-packages\wandb\sdk\lib\sock_client.py", line 174, in send_record_publish
    self.send_server_request(server_req)
  File "C:\ProgramData\anaconda3\envs\di725-a2-clean\lib\site-packages\wandb\sdk\lib\sock_client.py", line 154, in send_server_request
    self._send_message(msg)
  File "C:\ProgramData\anaconda3\envs\di725-a2-clean\lib\site-packages\wandb\sdk\lib\sock_client.py", line 151, in _send_message
    self._sendall_with_error_handle(header + data)
  File "C:\ProgramData\anaconda3\envs\di725-a2-clean\lib\site-packages\wandb\sdk\lib\sock_client.py", line 130, in _sendall_with_error_handle
    sent = self._sock.send(data)
ConnectionResetError: [WinError 10054] An existing connection was forcibly closed by the remote host
2025-04-20 20:17:12,253 ERROR   MainThread:27936 [redirect.py:_on_write():661] [no run ID] error in stderr callback
Traceback (most recent call last):
  File "C:\ProgramData\anaconda3\envs\di725-a2-clean\lib\site-packages\wandb\sdk\lib\redirect.py", line 659, in _on_write
    cb(written_data)
  File "C:\ProgramData\anaconda3\envs\di725-a2-clean\lib\site-packages\wandb\sdk\wandb_run.py", line 2381, in <lambda>
    lambda data: self._console_raw_callback("stderr", data),
  File "C:\ProgramData\anaconda3\envs\di725-a2-clean\lib\site-packages\wandb\sdk\wandb_run.py", line 387, in wrapper
    return func(self, *args, **kwargs)
  File "C:\ProgramData\anaconda3\envs\di725-a2-clean\lib\site-packages\wandb\sdk\wandb_run.py", line 435, in wrapper_fn
    return func(self, *args, **kwargs)
  File "C:\ProgramData\anaconda3\envs\di725-a2-clean\lib\site-packages\wandb\sdk\wandb_run.py", line 1518, in _console_raw_callback
    self._backend.interface.publish_output_raw(name, data)
  File "C:\ProgramData\anaconda3\envs\di725-a2-clean\lib\site-packages\wandb\sdk\interface\interface.py", line 761, in publish_output_raw
    self._publish_output_raw(o)
  File "C:\ProgramData\anaconda3\envs\di725-a2-clean\lib\site-packages\wandb\sdk\interface\interface_shared.py", line 38, in _publish_output_raw
    self._publish(rec)
  File "C:\ProgramData\anaconda3\envs\di725-a2-clean\lib\site-packages\wandb\sdk\interface\interface_sock.py", line 39, in _publish
    self._sock_client.send_record_publish(record)
  File "C:\ProgramData\anaconda3\envs\di725-a2-clean\lib\site-packages\wandb\sdk\lib\sock_client.py", line 174, in send_record_publish
    self.send_server_request(server_req)
  File "C:\ProgramData\anaconda3\envs\di725-a2-clean\lib\site-packages\wandb\sdk\lib\sock_client.py", line 154, in send_server_request
    self._send_message(msg)
  File "C:\ProgramData\anaconda3\envs\di725-a2-clean\lib\site-packages\wandb\sdk\lib\sock_client.py", line 151, in _send_message
    self._sendall_with_error_handle(header + data)
  File "C:\ProgramData\anaconda3\envs\di725-a2-clean\lib\site-packages\wandb\sdk\lib\sock_client.py", line 130, in _sendall_with_error_handle
    sent = self._sock.send(data)
ConnectionResetError: [WinError 10054] An existing connection was forcibly closed by the remote host
2025-04-20 20:17:12,254 ERROR   MainThread:27936 [redirect.py:_on_write():661] [no run ID] error in stderr callback
Traceback (most recent call last):
  File "C:\ProgramData\anaconda3\envs\di725-a2-clean\lib\site-packages\wandb\sdk\lib\redirect.py", line 659, in _on_write
    cb(written_data)
  File "C:\ProgramData\anaconda3\envs\di725-a2-clean\lib\site-packages\wandb\sdk\wandb_run.py", line 2381, in <lambda>
    lambda data: self._console_raw_callback("stderr", data),
  File "C:\ProgramData\anaconda3\envs\di725-a2-clean\lib\site-packages\wandb\sdk\wandb_run.py", line 387, in wrapper
    return func(self, *args, **kwargs)
  File "C:\ProgramData\anaconda3\envs\di725-a2-clean\lib\site-packages\wandb\sdk\wandb_run.py", line 435, in wrapper_fn
    return func(self, *args, **kwargs)
  File "C:\ProgramData\anaconda3\envs\di725-a2-clean\lib\site-packages\wandb\sdk\wandb_run.py", line 1518, in _console_raw_callback
    self._backend.interface.publish_output_raw(name, data)
  File "C:\ProgramData\anaconda3\envs\di725-a2-clean\lib\site-packages\wandb\sdk\interface\interface.py", line 761, in publish_output_raw
    self._publish_output_raw(o)
  File "C:\ProgramData\anaconda3\envs\di725-a2-clean\lib\site-packages\wandb\sdk\interface\interface_shared.py", line 38, in _publish_output_raw
    self._publish(rec)
  File "C:\ProgramData\anaconda3\envs\di725-a2-clean\lib\site-packages\wandb\sdk\interface\interface_sock.py", line 39, in _publish
    self._sock_client.send_record_publish(record)
  File "C:\ProgramData\anaconda3\envs\di725-a2-clean\lib\site-packages\wandb\sdk\lib\sock_client.py", line 174, in send_record_publish
    self.send_server_request(server_req)
  File "C:\ProgramData\anaconda3\envs\di725-a2-clean\lib\site-packages\wandb\sdk\lib\sock_client.py", line 154, in send_server_request
    self._send_message(msg)
  File "C:\ProgramData\anaconda3\envs\di725-a2-clean\lib\site-packages\wandb\sdk\lib\sock_client.py", line 151, in _send_message
    self._sendall_with_error_handle(header + data)
  File "C:\ProgramData\anaconda3\envs\di725-a2-clean\lib\site-packages\wandb\sdk\lib\sock_client.py", line 130, in _sendall_with_error_handle
    sent = self._sock.send(data)
ConnectionResetError: [WinError 10054] An existing connection was forcibly closed by the remote host
2025-04-20 20:17:12,255 ERROR   MainThread:27936 [redirect.py:_on_write():661] [no run ID] error in stderr callback
Traceback (most recent call last):
  File "C:\ProgramData\anaconda3\envs\di725-a2-clean\lib\site-packages\wandb\sdk\lib\redirect.py", line 659, in _on_write
    cb(written_data)
  File "C:\ProgramData\anaconda3\envs\di725-a2-clean\lib\site-packages\wandb\sdk\wandb_run.py", line 2381, in <lambda>
    lambda data: self._console_raw_callback("stderr", data),
  File "C:\ProgramData\anaconda3\envs\di725-a2-clean\lib\site-packages\wandb\sdk\wandb_run.py", line 387, in wrapper
    return func(self, *args, **kwargs)
  File "C:\ProgramData\anaconda3\envs\di725-a2-clean\lib\site-packages\wandb\sdk\wandb_run.py", line 435, in wrapper_fn
    return func(self, *args, **kwargs)
  File "C:\ProgramData\anaconda3\envs\di725-a2-clean\lib\site-packages\wandb\sdk\wandb_run.py", line 1518, in _console_raw_callback
    self._backend.interface.publish_output_raw(name, data)
  File "C:\ProgramData\anaconda3\envs\di725-a2-clean\lib\site-packages\wandb\sdk\interface\interface.py", line 761, in publish_output_raw
    self._publish_output_raw(o)
  File "C:\ProgramData\anaconda3\envs\di725-a2-clean\lib\site-packages\wandb\sdk\interface\interface_shared.py", line 38, in _publish_output_raw
    self._publish(rec)
  File "C:\ProgramData\anaconda3\envs\di725-a2-clean\lib\site-packages\wandb\sdk\interface\interface_sock.py", line 39, in _publish
    self._sock_client.send_record_publish(record)
  File "C:\ProgramData\anaconda3\envs\di725-a2-clean\lib\site-packages\wandb\sdk\lib\sock_client.py", line 174, in send_record_publish
    self.send_server_request(server_req)
  File "C:\ProgramData\anaconda3\envs\di725-a2-clean\lib\site-packages\wandb\sdk\lib\sock_client.py", line 154, in send_server_request
    self._send_message(msg)
  File "C:\ProgramData\anaconda3\envs\di725-a2-clean\lib\site-packages\wandb\sdk\lib\sock_client.py", line 151, in _send_message
    self._sendall_with_error_handle(header + data)
  File "C:\ProgramData\anaconda3\envs\di725-a2-clean\lib\site-packages\wandb\sdk\lib\sock_client.py", line 130, in _sendall_with_error_handle
    sent = self._sock.send(data)
ConnectionResetError: [WinError 10054] An existing connection was forcibly closed by the remote host
2025-04-20 20:17:12,256 ERROR   MainThread:27936 [redirect.py:_on_write():661] [no run ID] error in stderr callback
Traceback (most recent call last):
  File "C:\ProgramData\anaconda3\envs\di725-a2-clean\lib\site-packages\wandb\sdk\lib\redirect.py", line 659, in _on_write
    cb(written_data)
  File "C:\ProgramData\anaconda3\envs\di725-a2-clean\lib\site-packages\wandb\sdk\wandb_run.py", line 2381, in <lambda>
    lambda data: self._console_raw_callback("stderr", data),
  File "C:\ProgramData\anaconda3\envs\di725-a2-clean\lib\site-packages\wandb\sdk\wandb_run.py", line 387, in wrapper
    return func(self, *args, **kwargs)
  File "C:\ProgramData\anaconda3\envs\di725-a2-clean\lib\site-packages\wandb\sdk\wandb_run.py", line 435, in wrapper_fn
    return func(self, *args, **kwargs)
  File "C:\ProgramData\anaconda3\envs\di725-a2-clean\lib\site-packages\wandb\sdk\wandb_run.py", line 1518, in _console_raw_callback
    self._backend.interface.publish_output_raw(name, data)
  File "C:\ProgramData\anaconda3\envs\di725-a2-clean\lib\site-packages\wandb\sdk\interface\interface.py", line 761, in publish_output_raw
    self._publish_output_raw(o)
  File "C:\ProgramData\anaconda3\envs\di725-a2-clean\lib\site-packages\wandb\sdk\interface\interface_shared.py", line 38, in _publish_output_raw
    self._publish(rec)
  File "C:\ProgramData\anaconda3\envs\di725-a2-clean\lib\site-packages\wandb\sdk\interface\interface_sock.py", line 39, in _publish
    self._sock_client.send_record_publish(record)
  File "C:\ProgramData\anaconda3\envs\di725-a2-clean\lib\site-packages\wandb\sdk\lib\sock_client.py", line 174, in send_record_publish
    self.send_server_request(server_req)
  File "C:\ProgramData\anaconda3\envs\di725-a2-clean\lib\site-packages\wandb\sdk\lib\sock_client.py", line 154, in send_server_request
    self._send_message(msg)
  File "C:\ProgramData\anaconda3\envs\di725-a2-clean\lib\site-packages\wandb\sdk\lib\sock_client.py", line 151, in _send_message
    self._sendall_with_error_handle(header + data)
  File "C:\ProgramData\anaconda3\envs\di725-a2-clean\lib\site-packages\wandb\sdk\lib\sock_client.py", line 130, in _sendall_with_error_handle
    sent = self._sock.send(data)
ConnectionResetError: [WinError 10054] An existing connection was forcibly closed by the remote host
2025-04-20 20:17:12,257 ERROR   MainThread:27936 [redirect.py:_on_write():661] [no run ID] error in stderr callback
Traceback (most recent call last):
  File "C:\ProgramData\anaconda3\envs\di725-a2-clean\lib\site-packages\wandb\sdk\lib\redirect.py", line 659, in _on_write
    cb(written_data)
  File "C:\ProgramData\anaconda3\envs\di725-a2-clean\lib\site-packages\wandb\sdk\wandb_run.py", line 2381, in <lambda>
    lambda data: self._console_raw_callback("stderr", data),
  File "C:\ProgramData\anaconda3\envs\di725-a2-clean\lib\site-packages\wandb\sdk\wandb_run.py", line 387, in wrapper
    return func(self, *args, **kwargs)
  File "C:\ProgramData\anaconda3\envs\di725-a2-clean\lib\site-packages\wandb\sdk\wandb_run.py", line 435, in wrapper_fn
    return func(self, *args, **kwargs)
  File "C:\ProgramData\anaconda3\envs\di725-a2-clean\lib\site-packages\wandb\sdk\wandb_run.py", line 1518, in _console_raw_callback
    self._backend.interface.publish_output_raw(name, data)
  File "C:\ProgramData\anaconda3\envs\di725-a2-clean\lib\site-packages\wandb\sdk\interface\interface.py", line 761, in publish_output_raw
    self._publish_output_raw(o)
  File "C:\ProgramData\anaconda3\envs\di725-a2-clean\lib\site-packages\wandb\sdk\interface\interface_shared.py", line 38, in _publish_output_raw
    self._publish(rec)
  File "C:\ProgramData\anaconda3\envs\di725-a2-clean\lib\site-packages\wandb\sdk\interface\interface_sock.py", line 39, in _publish
    self._sock_client.send_record_publish(record)
  File "C:\ProgramData\anaconda3\envs\di725-a2-clean\lib\site-packages\wandb\sdk\lib\sock_client.py", line 174, in send_record_publish
    self.send_server_request(server_req)
  File "C:\ProgramData\anaconda3\envs\di725-a2-clean\lib\site-packages\wandb\sdk\lib\sock_client.py", line 154, in send_server_request
    self._send_message(msg)
  File "C:\ProgramData\anaconda3\envs\di725-a2-clean\lib\site-packages\wandb\sdk\lib\sock_client.py", line 151, in _send_message
    self._sendall_with_error_handle(header + data)
  File "C:\ProgramData\anaconda3\envs\di725-a2-clean\lib\site-packages\wandb\sdk\lib\sock_client.py", line 130, in _sendall_with_error_handle
    sent = self._sock.send(data)
ConnectionResetError: [WinError 10054] An existing connection was forcibly closed by the remote host
2025-04-20 20:17:12,258 ERROR   MainThread:27936 [redirect.py:_on_write():661] [no run ID] error in stderr callback
Traceback (most recent call last):
  File "C:\ProgramData\anaconda3\envs\di725-a2-clean\lib\site-packages\wandb\sdk\lib\redirect.py", line 659, in _on_write
    cb(written_data)
  File "C:\ProgramData\anaconda3\envs\di725-a2-clean\lib\site-packages\wandb\sdk\wandb_run.py", line 2381, in <lambda>
    lambda data: self._console_raw_callback("stderr", data),
  File "C:\ProgramData\anaconda3\envs\di725-a2-clean\lib\site-packages\wandb\sdk\wandb_run.py", line 387, in wrapper
    return func(self, *args, **kwargs)
  File "C:\ProgramData\anaconda3\envs\di725-a2-clean\lib\site-packages\wandb\sdk\wandb_run.py", line 435, in wrapper_fn
    return func(self, *args, **kwargs)
  File "C:\ProgramData\anaconda3\envs\di725-a2-clean\lib\site-packages\wandb\sdk\wandb_run.py", line 1518, in _console_raw_callback
    self._backend.interface.publish_output_raw(name, data)
  File "C:\ProgramData\anaconda3\envs\di725-a2-clean\lib\site-packages\wandb\sdk\interface\interface.py", line 761, in publish_output_raw
    self._publish_output_raw(o)
  File "C:\ProgramData\anaconda3\envs\di725-a2-clean\lib\site-packages\wandb\sdk\interface\interface_shared.py", line 38, in _publish_output_raw
    self._publish(rec)
  File "C:\ProgramData\anaconda3\envs\di725-a2-clean\lib\site-packages\wandb\sdk\interface\interface_sock.py", line 39, in _publish
    self._sock_client.send_record_publish(record)
  File "C:\ProgramData\anaconda3\envs\di725-a2-clean\lib\site-packages\wandb\sdk\lib\sock_client.py", line 174, in send_record_publish
    self.send_server_request(server_req)
  File "C:\ProgramData\anaconda3\envs\di725-a2-clean\lib\site-packages\wandb\sdk\lib\sock_client.py", line 154, in send_server_request
    self._send_message(msg)
  File "C:\ProgramData\anaconda3\envs\di725-a2-clean\lib\site-packages\wandb\sdk\lib\sock_client.py", line 151, in _send_message
    self._sendall_with_error_handle(header + data)
  File "C:\ProgramData\anaconda3\envs\di725-a2-clean\lib\site-packages\wandb\sdk\lib\sock_client.py", line 130, in _sendall_with_error_handle
    sent = self._sock.send(data)
ConnectionResetError: [WinError 10054] An existing connection was forcibly closed by the remote host
2025-04-20 20:17:12,259 ERROR   MainThread:27936 [redirect.py:_on_write():661] [no run ID] error in stderr callback
Traceback (most recent call last):
  File "C:\ProgramData\anaconda3\envs\di725-a2-clean\lib\site-packages\wandb\sdk\lib\redirect.py", line 659, in _on_write
    cb(written_data)
  File "C:\ProgramData\anaconda3\envs\di725-a2-clean\lib\site-packages\wandb\sdk\wandb_run.py", line 2381, in <lambda>
    lambda data: self._console_raw_callback("stderr", data),
  File "C:\ProgramData\anaconda3\envs\di725-a2-clean\lib\site-packages\wandb\sdk\wandb_run.py", line 387, in wrapper
    return func(self, *args, **kwargs)
  File "C:\ProgramData\anaconda3\envs\di725-a2-clean\lib\site-packages\wandb\sdk\wandb_run.py", line 435, in wrapper_fn
    return func(self, *args, **kwargs)
  File "C:\ProgramData\anaconda3\envs\di725-a2-clean\lib\site-packages\wandb\sdk\wandb_run.py", line 1518, in _console_raw_callback
    self._backend.interface.publish_output_raw(name, data)
  File "C:\ProgramData\anaconda3\envs\di725-a2-clean\lib\site-packages\wandb\sdk\interface\interface.py", line 761, in publish_output_raw
    self._publish_output_raw(o)
  File "C:\ProgramData\anaconda3\envs\di725-a2-clean\lib\site-packages\wandb\sdk\interface\interface_shared.py", line 38, in _publish_output_raw
    self._publish(rec)
  File "C:\ProgramData\anaconda3\envs\di725-a2-clean\lib\site-packages\wandb\sdk\interface\interface_sock.py", line 39, in _publish
    self._sock_client.send_record_publish(record)
  File "C:\ProgramData\anaconda3\envs\di725-a2-clean\lib\site-packages\wandb\sdk\lib\sock_client.py", line 174, in send_record_publish
    self.send_server_request(server_req)
  File "C:\ProgramData\anaconda3\envs\di725-a2-clean\lib\site-packages\wandb\sdk\lib\sock_client.py", line 154, in send_server_request
    self._send_message(msg)
  File "C:\ProgramData\anaconda3\envs\di725-a2-clean\lib\site-packages\wandb\sdk\lib\sock_client.py", line 151, in _send_message
    self._sendall_with_error_handle(header + data)
  File "C:\ProgramData\anaconda3\envs\di725-a2-clean\lib\site-packages\wandb\sdk\lib\sock_client.py", line 130, in _sendall_with_error_handle
    sent = self._sock.send(data)
ConnectionResetError: [WinError 10054] An existing connection was forcibly closed by the remote host
2025-04-20 20:17:12,260 ERROR   MainThread:27936 [redirect.py:_on_write():661] [no run ID] error in stderr callback
Traceback (most recent call last):
  File "C:\ProgramData\anaconda3\envs\di725-a2-clean\lib\site-packages\wandb\sdk\lib\redirect.py", line 659, in _on_write
    cb(written_data)
  File "C:\ProgramData\anaconda3\envs\di725-a2-clean\lib\site-packages\wandb\sdk\wandb_run.py", line 2381, in <lambda>
    lambda data: self._console_raw_callback("stderr", data),
  File "C:\ProgramData\anaconda3\envs\di725-a2-clean\lib\site-packages\wandb\sdk\wandb_run.py", line 387, in wrapper
    return func(self, *args, **kwargs)
  File "C:\ProgramData\anaconda3\envs\di725-a2-clean\lib\site-packages\wandb\sdk\wandb_run.py", line 435, in wrapper_fn
    return func(self, *args, **kwargs)
  File "C:\ProgramData\anaconda3\envs\di725-a2-clean\lib\site-packages\wandb\sdk\wandb_run.py", line 1518, in _console_raw_callback
    self._backend.interface.publish_output_raw(name, data)
  File "C:\ProgramData\anaconda3\envs\di725-a2-clean\lib\site-packages\wandb\sdk\interface\interface.py", line 761, in publish_output_raw
    self._publish_output_raw(o)
  File "C:\ProgramData\anaconda3\envs\di725-a2-clean\lib\site-packages\wandb\sdk\interface\interface_shared.py", line 38, in _publish_output_raw
    self._publish(rec)
  File "C:\ProgramData\anaconda3\envs\di725-a2-clean\lib\site-packages\wandb\sdk\interface\interface_sock.py", line 39, in _publish
    self._sock_client.send_record_publish(record)
  File "C:\ProgramData\anaconda3\envs\di725-a2-clean\lib\site-packages\wandb\sdk\lib\sock_client.py", line 174, in send_record_publish
    self.send_server_request(server_req)
  File "C:\ProgramData\anaconda3\envs\di725-a2-clean\lib\site-packages\wandb\sdk\lib\sock_client.py", line 154, in send_server_request
    self._send_message(msg)
  File "C:\ProgramData\anaconda3\envs\di725-a2-clean\lib\site-packages\wandb\sdk\lib\sock_client.py", line 151, in _send_message
    self._sendall_with_error_handle(header + data)
  File "C:\ProgramData\anaconda3\envs\di725-a2-clean\lib\site-packages\wandb\sdk\lib\sock_client.py", line 130, in _sendall_with_error_handle
    sent = self._sock.send(data)
ConnectionResetError: [WinError 10054] An existing connection was forcibly closed by the remote host
2025-04-20 20:17:12,261 ERROR   MainThread:27936 [redirect.py:_on_write():661] [no run ID] error in stderr callback
Traceback (most recent call last):
  File "C:\ProgramData\anaconda3\envs\di725-a2-clean\lib\site-packages\wandb\sdk\lib\redirect.py", line 659, in _on_write
    cb(written_data)
  File "C:\ProgramData\anaconda3\envs\di725-a2-clean\lib\site-packages\wandb\sdk\wandb_run.py", line 2381, in <lambda>
    lambda data: self._console_raw_callback("stderr", data),
  File "C:\ProgramData\anaconda3\envs\di725-a2-clean\lib\site-packages\wandb\sdk\wandb_run.py", line 387, in wrapper
    return func(self, *args, **kwargs)
  File "C:\ProgramData\anaconda3\envs\di725-a2-clean\lib\site-packages\wandb\sdk\wandb_run.py", line 435, in wrapper_fn
    return func(self, *args, **kwargs)
  File "C:\ProgramData\anaconda3\envs\di725-a2-clean\lib\site-packages\wandb\sdk\wandb_run.py", line 1518, in _console_raw_callback
    self._backend.interface.publish_output_raw(name, data)
  File "C:\ProgramData\anaconda3\envs\di725-a2-clean\lib\site-packages\wandb\sdk\interface\interface.py", line 761, in publish_output_raw
    self._publish_output_raw(o)
  File "C:\ProgramData\anaconda3\envs\di725-a2-clean\lib\site-packages\wandb\sdk\interface\interface_shared.py", line 38, in _publish_output_raw
    self._publish(rec)
  File "C:\ProgramData\anaconda3\envs\di725-a2-clean\lib\site-packages\wandb\sdk\interface\interface_sock.py", line 39, in _publish
    self._sock_client.send_record_publish(record)
  File "C:\ProgramData\anaconda3\envs\di725-a2-clean\lib\site-packages\wandb\sdk\lib\sock_client.py", line 174, in send_record_publish
    self.send_server_request(server_req)
  File "C:\ProgramData\anaconda3\envs\di725-a2-clean\lib\site-packages\wandb\sdk\lib\sock_client.py", line 154, in send_server_request
    self._send_message(msg)
  File "C:\ProgramData\anaconda3\envs\di725-a2-clean\lib\site-packages\wandb\sdk\lib\sock_client.py", line 151, in _send_message
    self._sendall_with_error_handle(header + data)
  File "C:\ProgramData\anaconda3\envs\di725-a2-clean\lib\site-packages\wandb\sdk\lib\sock_client.py", line 130, in _sendall_with_error_handle
    sent = self._sock.send(data)
ConnectionResetError: [WinError 10054] An existing connection was forcibly closed by the remote host
2025-04-20 20:17:12,262 ERROR   MainThread:27936 [redirect.py:_on_write():661] [no run ID] error in stderr callback
Traceback (most recent call last):
  File "C:\ProgramData\anaconda3\envs\di725-a2-clean\lib\site-packages\wandb\sdk\lib\redirect.py", line 659, in _on_write
    cb(written_data)
  File "C:\ProgramData\anaconda3\envs\di725-a2-clean\lib\site-packages\wandb\sdk\wandb_run.py", line 2381, in <lambda>
    lambda data: self._console_raw_callback("stderr", data),
  File "C:\ProgramData\anaconda3\envs\di725-a2-clean\lib\site-packages\wandb\sdk\wandb_run.py", line 387, in wrapper
    return func(self, *args, **kwargs)
  File "C:\ProgramData\anaconda3\envs\di725-a2-clean\lib\site-packages\wandb\sdk\wandb_run.py", line 435, in wrapper_fn
    return func(self, *args, **kwargs)
  File "C:\ProgramData\anaconda3\envs\di725-a2-clean\lib\site-packages\wandb\sdk\wandb_run.py", line 1518, in _console_raw_callback
    self._backend.interface.publish_output_raw(name, data)
  File "C:\ProgramData\anaconda3\envs\di725-a2-clean\lib\site-packages\wandb\sdk\interface\interface.py", line 761, in publish_output_raw
    self._publish_output_raw(o)
  File "C:\ProgramData\anaconda3\envs\di725-a2-clean\lib\site-packages\wandb\sdk\interface\interface_shared.py", line 38, in _publish_output_raw
    self._publish(rec)
  File "C:\ProgramData\anaconda3\envs\di725-a2-clean\lib\site-packages\wandb\sdk\interface\interface_sock.py", line 39, in _publish
    self._sock_client.send_record_publish(record)
  File "C:\ProgramData\anaconda3\envs\di725-a2-clean\lib\site-packages\wandb\sdk\lib\sock_client.py", line 174, in send_record_publish
    self.send_server_request(server_req)
  File "C:\ProgramData\anaconda3\envs\di725-a2-clean\lib\site-packages\wandb\sdk\lib\sock_client.py", line 154, in send_server_request
    self._send_message(msg)
  File "C:\ProgramData\anaconda3\envs\di725-a2-clean\lib\site-packages\wandb\sdk\lib\sock_client.py", line 151, in _send_message
    self._sendall_with_error_handle(header + data)
  File "C:\ProgramData\anaconda3\envs\di725-a2-clean\lib\site-packages\wandb\sdk\lib\sock_client.py", line 130, in _sendall_with_error_handle
    sent = self._sock.send(data)
ConnectionResetError: [WinError 10054] An existing connection was forcibly closed by the remote host
2025-04-20 20:17:12,263 ERROR   MainThread:27936 [redirect.py:_on_write():661] [no run ID] error in stderr callback
Traceback (most recent call last):
  File "C:\ProgramData\anaconda3\envs\di725-a2-clean\lib\site-packages\wandb\sdk\lib\redirect.py", line 659, in _on_write
    cb(written_data)
  File "C:\ProgramData\anaconda3\envs\di725-a2-clean\lib\site-packages\wandb\sdk\wandb_run.py", line 2381, in <lambda>
    lambda data: self._console_raw_callback("stderr", data),
  File "C:\ProgramData\anaconda3\envs\di725-a2-clean\lib\site-packages\wandb\sdk\wandb_run.py", line 387, in wrapper
    return func(self, *args, **kwargs)
  File "C:\ProgramData\anaconda3\envs\di725-a2-clean\lib\site-packages\wandb\sdk\wandb_run.py", line 435, in wrapper_fn
    return func(self, *args, **kwargs)
  File "C:\ProgramData\anaconda3\envs\di725-a2-clean\lib\site-packages\wandb\sdk\wandb_run.py", line 1518, in _console_raw_callback
    self._backend.interface.publish_output_raw(name, data)
  File "C:\ProgramData\anaconda3\envs\di725-a2-clean\lib\site-packages\wandb\sdk\interface\interface.py", line 761, in publish_output_raw
    self._publish_output_raw(o)
  File "C:\ProgramData\anaconda3\envs\di725-a2-clean\lib\site-packages\wandb\sdk\interface\interface_shared.py", line 38, in _publish_output_raw
    self._publish(rec)
  File "C:\ProgramData\anaconda3\envs\di725-a2-clean\lib\site-packages\wandb\sdk\interface\interface_sock.py", line 39, in _publish
    self._sock_client.send_record_publish(record)
  File "C:\ProgramData\anaconda3\envs\di725-a2-clean\lib\site-packages\wandb\sdk\lib\sock_client.py", line 174, in send_record_publish
    self.send_server_request(server_req)
  File "C:\ProgramData\anaconda3\envs\di725-a2-clean\lib\site-packages\wandb\sdk\lib\sock_client.py", line 154, in send_server_request
    self._send_message(msg)
  File "C:\ProgramData\anaconda3\envs\di725-a2-clean\lib\site-packages\wandb\sdk\lib\sock_client.py", line 151, in _send_message
    self._sendall_with_error_handle(header + data)
  File "C:\ProgramData\anaconda3\envs\di725-a2-clean\lib\site-packages\wandb\sdk\lib\sock_client.py", line 130, in _sendall_with_error_handle
    sent = self._sock.send(data)
ConnectionResetError: [WinError 10054] An existing connection was forcibly closed by the remote host
2025-04-20 20:17:12,264 ERROR   MainThread:27936 [redirect.py:_on_write():661] [no run ID] error in stderr callback
Traceback (most recent call last):
  File "C:\ProgramData\anaconda3\envs\di725-a2-clean\lib\site-packages\wandb\sdk\lib\redirect.py", line 659, in _on_write
    cb(written_data)
  File "C:\ProgramData\anaconda3\envs\di725-a2-clean\lib\site-packages\wandb\sdk\wandb_run.py", line 2381, in <lambda>
    lambda data: self._console_raw_callback("stderr", data),
  File "C:\ProgramData\anaconda3\envs\di725-a2-clean\lib\site-packages\wandb\sdk\wandb_run.py", line 387, in wrapper
    return func(self, *args, **kwargs)
  File "C:\ProgramData\anaconda3\envs\di725-a2-clean\lib\site-packages\wandb\sdk\wandb_run.py", line 435, in wrapper_fn
    return func(self, *args, **kwargs)
  File "C:\ProgramData\anaconda3\envs\di725-a2-clean\lib\site-packages\wandb\sdk\wandb_run.py", line 1518, in _console_raw_callback
    self._backend.interface.publish_output_raw(name, data)
  File "C:\ProgramData\anaconda3\envs\di725-a2-clean\lib\site-packages\wandb\sdk\interface\interface.py", line 761, in publish_output_raw
    self._publish_output_raw(o)
  File "C:\ProgramData\anaconda3\envs\di725-a2-clean\lib\site-packages\wandb\sdk\interface\interface_shared.py", line 38, in _publish_output_raw
    self._publish(rec)
  File "C:\ProgramData\anaconda3\envs\di725-a2-clean\lib\site-packages\wandb\sdk\interface\interface_sock.py", line 39, in _publish
    self._sock_client.send_record_publish(record)
  File "C:\ProgramData\anaconda3\envs\di725-a2-clean\lib\site-packages\wandb\sdk\lib\sock_client.py", line 174, in send_record_publish
    self.send_server_request(server_req)
  File "C:\ProgramData\anaconda3\envs\di725-a2-clean\lib\site-packages\wandb\sdk\lib\sock_client.py", line 154, in send_server_request
    self._send_message(msg)
  File "C:\ProgramData\anaconda3\envs\di725-a2-clean\lib\site-packages\wandb\sdk\lib\sock_client.py", line 151, in _send_message
    self._sendall_with_error_handle(header + data)
  File "C:\ProgramData\anaconda3\envs\di725-a2-clean\lib\site-packages\wandb\sdk\lib\sock_client.py", line 130, in _sendall_with_error_handle
    sent = self._sock.send(data)
ConnectionResetError: [WinError 10054] An existing connection was forcibly closed by the remote host
2025-04-20 20:17:12,265 ERROR   MainThread:27936 [redirect.py:_on_write():661] [no run ID] error in stderr callback
Traceback (most recent call last):
  File "C:\ProgramData\anaconda3\envs\di725-a2-clean\lib\site-packages\wandb\sdk\lib\redirect.py", line 659, in _on_write
    cb(written_data)
  File "C:\ProgramData\anaconda3\envs\di725-a2-clean\lib\site-packages\wandb\sdk\wandb_run.py", line 2381, in <lambda>
    lambda data: self._console_raw_callback("stderr", data),
  File "C:\ProgramData\anaconda3\envs\di725-a2-clean\lib\site-packages\wandb\sdk\wandb_run.py", line 387, in wrapper
    return func(self, *args, **kwargs)
  File "C:\ProgramData\anaconda3\envs\di725-a2-clean\lib\site-packages\wandb\sdk\wandb_run.py", line 435, in wrapper_fn
    return func(self, *args, **kwargs)
  File "C:\ProgramData\anaconda3\envs\di725-a2-clean\lib\site-packages\wandb\sdk\wandb_run.py", line 1518, in _console_raw_callback
    self._backend.interface.publish_output_raw(name, data)
  File "C:\ProgramData\anaconda3\envs\di725-a2-clean\lib\site-packages\wandb\sdk\interface\interface.py", line 761, in publish_output_raw
    self._publish_output_raw(o)
  File "C:\ProgramData\anaconda3\envs\di725-a2-clean\lib\site-packages\wandb\sdk\interface\interface_shared.py", line 38, in _publish_output_raw
    self._publish(rec)
  File "C:\ProgramData\anaconda3\envs\di725-a2-clean\lib\site-packages\wandb\sdk\interface\interface_sock.py", line 39, in _publish
    self._sock_client.send_record_publish(record)
  File "C:\ProgramData\anaconda3\envs\di725-a2-clean\lib\site-packages\wandb\sdk\lib\sock_client.py", line 174, in send_record_publish
    self.send_server_request(server_req)
  File "C:\ProgramData\anaconda3\envs\di725-a2-clean\lib\site-packages\wandb\sdk\lib\sock_client.py", line 154, in send_server_request
    self._send_message(msg)
  File "C:\ProgramData\anaconda3\envs\di725-a2-clean\lib\site-packages\wandb\sdk\lib\sock_client.py", line 151, in _send_message
    self._sendall_with_error_handle(header + data)
  File "C:\ProgramData\anaconda3\envs\di725-a2-clean\lib\site-packages\wandb\sdk\lib\sock_client.py", line 130, in _sendall_with_error_handle
    sent = self._sock.send(data)
ConnectionResetError: [WinError 10054] An existing connection was forcibly closed by the remote host
